[Wed Aug 09 23:01:07.220734 2017] [cgi:error] [pid 1213] [client 127.0.0.1:57316] AH01215: Traceback (most recent call last):
[Wed Aug 09 23:01:07.220877 2017] [cgi:error] [pid 1213] [client 127.0.0.1:57316] AH01215:   File "/home/debian/server/crm/rootsystem/application/xfc.py", line 12, in <module>
[Wed Aug 09 23:01:07.220893 2017] [cgi:error] [pid 1213] [client 127.0.0.1:57316] AH01215:     recurso = uri[2]
[Wed Aug 09 23:01:07.220909 2017] [cgi:error] [pid 1213] [client 127.0.0.1:57316] AH01215: IndexError: list index out of range
[Wed Aug 09 23:01:07.223038 2017] [cgi:error] [pid 1213] [client 127.0.0.1:57316] End of script output before headers: xfc.py
[Wed Aug 09 23:01:07.497878 2017] [cgi:error] [pid 1214] [client 127.0.0.1:57318] AH01215: Traceback (most recent call last):
[Wed Aug 09 23:01:07.497998 2017] [cgi:error] [pid 1214] [client 127.0.0.1:57318] AH01215:   File "/home/debian/server/crm/rootsystem/application/xfc.py", line 12, in <module>
[Wed Aug 09 23:01:07.498011 2017] [cgi:error] [pid 1214] [client 127.0.0.1:57318] AH01215:     recurso = uri[2]
[Wed Aug 09 23:01:07.498028 2017] [cgi:error] [pid 1214] [client 127.0.0.1:57318] AH01215: IndexError: list index out of range
[Wed Aug 09 23:01:07.501912 2017] [cgi:error] [pid 1214] [client 127.0.0.1:57318] End of script output before headers: xfc.py
[Wed Aug 09 23:01:07.694623 2017] [cgi:error] [pid 1215] [client 127.0.0.1:57320] AH01215: Traceback (most recent call last):
[Wed Aug 09 23:01:07.694741 2017] [cgi:error] [pid 1215] [client 127.0.0.1:57320] AH01215:   File "/home/debian/server/crm/rootsystem/application/xfc.py", line 12, in <module>
[Wed Aug 09 23:01:07.694754 2017] [cgi:error] [pid 1215] [client 127.0.0.1:57320] AH01215:     recurso = uri[2]
[Wed Aug 09 23:01:07.694771 2017] [cgi:error] [pid 1215] [client 127.0.0.1:57320] AH01215: IndexError: list index out of range
[Wed Aug 09 23:01:07.696272 2017] [cgi:error] [pid 1215] [client 127.0.0.1:57320] End of script output before headers: xfc.py
[Wed Aug 09 23:02:59.869818 2017] [cgi:error] [pid 1212] [client 127.0.0.1:57322] AH01215: Traceback (most recent call last):
[Wed Aug 09 23:02:59.869938 2017] [cgi:error] [pid 1212] [client 127.0.0.1:57322] AH01215:   File "/home/debian/server/crm/rootsystem/application/xfc.py", line 12, in <module>
[Wed Aug 09 23:02:59.869948 2017] [cgi:error] [pid 1212] [client 127.0.0.1:57322] AH01215:     recurso = uri[2]
[Wed Aug 09 23:02:59.869958 2017] [cgi:error] [pid 1212] [client 127.0.0.1:57322] AH01215: IndexError: list index out of range
[Wed Aug 09 23:02:59.871774 2017] [cgi:error] [pid 1212] [client 127.0.0.1:57322] End of script output before headers: xfc.py
[Thu Aug 10 06:56:44.672125 2017] [cgi:error] [pid 1199] [client 127.0.0.1:57698] AH01215: Traceback (most recent call last):
[Thu Aug 10 06:56:44.672272 2017] [cgi:error] [pid 1199] [client 127.0.0.1:57698] AH01215:   File "/home/debian/server/crm/rootsystem/application/xfc.py", line 12, in <module>
[Thu Aug 10 06:56:44.672288 2017] [cgi:error] [pid 1199] [client 127.0.0.1:57698] AH01215:     recurso = uri[2]
[Thu Aug 10 06:56:44.672306 2017] [cgi:error] [pid 1199] [client 127.0.0.1:57698] AH01215: IndexError: list index out of range
[Thu Aug 10 06:56:44.674298 2017] [cgi:error] [pid 1199] [client 127.0.0.1:57698] End of script output before headers: xfc.py
[Thu Aug 10 06:56:45.303594 2017] [cgi:error] [pid 1203] [client 127.0.0.1:57700] AH01215: Traceback (most recent call last):
[Thu Aug 10 06:56:45.303723 2017] [cgi:error] [pid 1203] [client 127.0.0.1:57700] AH01215:   File "/home/debian/server/crm/rootsystem/application/xfc.py", line 12, in <module>
[Thu Aug 10 06:56:45.303742 2017] [cgi:error] [pid 1203] [client 127.0.0.1:57700] AH01215:     recurso = uri[2]
[Thu Aug 10 06:56:45.303761 2017] [cgi:error] [pid 1203] [client 127.0.0.1:57700] AH01215: IndexError: list index out of range
[Thu Aug 10 06:56:45.305436 2017] [cgi:error] [pid 1203] [client 127.0.0.1:57700] End of script output before headers: xfc.py
[Thu Aug 10 07:00:43.626241 2017] [cgi:error] [pid 1202] [client 127.0.0.1:57788] AH01215: Traceback (most recent call last):
[Thu Aug 10 07:00:43.626366 2017] [cgi:error] [pid 1202] [client 127.0.0.1:57788] AH01215:   File "/home/debian/server/crm/rootsystem/application/xfc.py", line 15, in <module>
[Thu Aug 10 07:00:43.626385 2017] [cgi:error] [pid 1202] [client 127.0.0.1:57788] AH01215:     m = __import__("modules.{}".format(modulo), fromlist=[controlador])
[Thu Aug 10 07:00:43.626416 2017] [cgi:error] [pid 1202] [client 127.0.0.1:57788] AH01215:   File "/home/debian/server/crm/rootsystem/application/modules/domicilio.py", line 49
[Thu Aug 10 07:00:43.626482 2017] [cgi:error] [pid 1202] [client 127.0.0.1:57788] AH01215: SyntaxError: Non-ASCII character '\\xc3' in file /home/debian/server/crm/rootsystem/application/modules/domicilio.py on line 49, but no encoding declared; see http://python.org/dev/peps/pep-0263/ for details
[Thu Aug 10 07:00:43.628027 2017] [cgi:error] [pid 1202] [client 127.0.0.1:57788] End of script output before headers: xfc.py
[Thu Aug 10 07:00:58.525953 2017] [cgi:error] [pid 1199] [client 127.0.0.1:57790] AH01215: Traceback (most recent call last):
[Thu Aug 10 07:00:58.526026 2017] [cgi:error] [pid 1199] [client 127.0.0.1:57790] AH01215:   File "/home/debian/server/crm/rootsystem/application/xfc.py", line 17, in <module>
[Thu Aug 10 07:00:58.526045 2017] [cgi:error] [pid 1199] [client 127.0.0.1:57790] AH01215:     getattr(c, recurso)()
[Thu Aug 10 07:00:58.526070 2017] [cgi:error] [pid 1199] [client 127.0.0.1:57790] AH01215: AttributeError: 'ProductoController' object has no attribute ''
[Thu Aug 10 07:00:58.527706 2017] [cgi:error] [pid 1199] [client 127.0.0.1:57790] End of script output before headers: xfc.py
[Thu Aug 10 07:04:37.268530 2017] [cgi:error] [pid 1203] [client 127.0.0.1:57796] AH01215: Traceback (most recent call last):
[Thu Aug 10 07:04:37.268607 2017] [cgi:error] [pid 1203] [client 127.0.0.1:57796] AH01215:   File "/home/debian/server/crm/rootsystem/application/xfc.py", line 15, in <module>
[Thu Aug 10 07:04:37.268639 2017] [cgi:error] [pid 1203] [client 127.0.0.1:57796] AH01215:     m = __import__("modules.{}".format(modulo), fromlist=[controlador])
[Thu Aug 10 07:04:37.268669 2017] [cgi:error] [pid 1203] [client 127.0.0.1:57796] AH01215:   File "/home/debian/server/crm/rootsystem/application/modules/domicilio.py", line 49
[Thu Aug 10 07:04:37.268722 2017] [cgi:error] [pid 1203] [client 127.0.0.1:57796] AH01215: SyntaxError: Non-ASCII character '\\xc3' in file /home/debian/server/crm/rootsystem/application/modules/domicilio.py on line 49, but no encoding declared; see http://python.org/dev/peps/pep-0263/ for details
[Thu Aug 10 07:04:37.270348 2017] [cgi:error] [pid 1203] [client 127.0.0.1:57796] End of script output before headers: xfc.py
[Thu Aug 10 07:05:33.482487 2017] [cgi:error] [pid 5190] [client 127.0.0.1:57798] AH01215: Traceback (most recent call last):
[Thu Aug 10 07:05:33.482580 2017] [cgi:error] [pid 5190] [client 127.0.0.1:57798] AH01215:   File "/home/debian/server/crm/rootsystem/application/xfc.py", line 15, in <module>
[Thu Aug 10 07:05:33.482612 2017] [cgi:error] [pid 5190] [client 127.0.0.1:57798] AH01215:     m = __import__("modules.{}".format(modulo), fromlist=[controlador])
[Thu Aug 10 07:05:33.482655 2017] [cgi:error] [pid 5190] [client 127.0.0.1:57798] AH01215:   File "/home/debian/server/crm/rootsystem/application/modules/domicilio.py", line 1, in <module>
[Thu Aug 10 07:05:33.482673 2017] [cgi:error] [pid 5190] [client 127.0.0.1:57798] AH01215:     class Domicilio(Object):
[Thu Aug 10 07:05:33.482697 2017] [cgi:error] [pid 5190] [client 127.0.0.1:57798] AH01215: NameError: name 'Object' is not defined
[Thu Aug 10 07:05:33.484212 2017] [cgi:error] [pid 5190] [client 127.0.0.1:57798] End of script output before headers: xfc.py
[Thu Aug 10 07:06:45.377635 2017] [cgi:error] [pid 1201] [client 127.0.0.1:57802] AH01215: Traceback (most recent call last):
[Thu Aug 10 07:06:45.377720 2017] [cgi:error] [pid 1201] [client 127.0.0.1:57802] AH01215:   File "/home/debian/server/crm/rootsystem/application/xfc.py", line 17, in <module>
[Thu Aug 10 07:06:45.377739 2017] [cgi:error] [pid 1201] [client 127.0.0.1:57802] AH01215:     getattr(c, recurso)()
[Thu Aug 10 07:06:45.377783 2017] [cgi:error] [pid 1201] [client 127.0.0.1:57802] AH01215: AttributeError: 'DomicilioController' object has no attribute 'guardado'
[Thu Aug 10 07:06:45.379412 2017] [cgi:error] [pid 1201] [client 127.0.0.1:57802] End of script output before headers: xfc.py
[Tue Aug 22 19:27:21.213952 2017] [cgi:error] [pid 2389] [client 127.0.0.1:40280] AH01215: Traceback (most recent call last):
[Tue Aug 22 19:27:21.420995 2017] [cgi:error] [pid 2389] [client 127.0.0.1:40280] AH01215:   File "/home/debian/server/crm/rootsystem/application/xfc.py", line 15, in <module>
[Tue Aug 22 19:27:21.421035 2017] [cgi:error] [pid 2389] [client 127.0.0.1:40280] AH01215:     m = __import__("modules.{}".format(modulo), fromlist=[controlador])
[Tue Aug 22 19:27:21.421051 2017] [cgi:error] [pid 2389] [client 127.0.0.1:40280] AH01215: ImportError: No module named agregar
[Tue Aug 22 19:27:21.421095 2017] [cgi:error] [pid 2389] [client 127.0.0.1:40280] End of script output before headers: xfc.py
[Tue Aug 22 19:27:21.740665 2017] [cgi:error] [pid 2386] [client 127.0.0.1:40282] AH01215: Traceback (most recent call last):
[Tue Aug 22 19:27:21.740755 2017] [cgi:error] [pid 2386] [client 127.0.0.1:40282] AH01215:   File "/home/debian/server/crm/rootsystem/application/xfc.py", line 12, in <module>
[Tue Aug 22 19:27:21.740768 2017] [cgi:error] [pid 2386] [client 127.0.0.1:40282] AH01215:     recurso = uri[2]
[Tue Aug 22 19:27:21.740803 2017] [cgi:error] [pid 2386] [client 127.0.0.1:40282] AH01215: IndexError: list index out of range
[Tue Aug 22 19:27:21.742506 2017] [cgi:error] [pid 2386] [client 127.0.0.1:40282] End of script output before headers: xfc.py
[Tue Aug 22 19:27:21.778767 2017] [cgi:error] [pid 2388] [client 127.0.0.1:40284] AH01215: Traceback (most recent call last):
[Tue Aug 22 19:27:21.778851 2017] [cgi:error] [pid 2388] [client 127.0.0.1:40284] AH01215:   File "/home/debian/server/crm/rootsystem/application/xfc.py", line 12, in <module>
[Tue Aug 22 19:27:21.778865 2017] [cgi:error] [pid 2388] [client 127.0.0.1:40284] AH01215:     recurso = uri[2]
[Tue Aug 22 19:27:21.778884 2017] [cgi:error] [pid 2388] [client 127.0.0.1:40284] AH01215: IndexError: list index out of range
[Tue Aug 22 19:27:21.780398 2017] [cgi:error] [pid 2388] [client 127.0.0.1:40284] End of script output before headers: xfc.py
[Tue Aug 22 19:27:34.203546 2017] [cgi:error] [pid 2387] [client 127.0.0.1:40286] AH01215: Traceback (most recent call last):
[Tue Aug 22 19:27:34.203615 2017] [cgi:error] [pid 2387] [client 127.0.0.1:40286] AH01215:   File "/home/debian/server/crm/rootsystem/application/xfc.py", line 15, in <module>
[Tue Aug 22 19:27:34.203633 2017] [cgi:error] [pid 2387] [client 127.0.0.1:40286] AH01215:     m = __import__("modules.{}".format(modulo), fromlist=[controlador])
[Tue Aug 22 19:27:34.203655 2017] [cgi:error] [pid 2387] [client 127.0.0.1:40286] AH01215:   File "/home/debian/server/crm/rootsystem/application/modules/producto.py", line 3, in <module>
[Tue Aug 22 19:27:34.203664 2017] [cgi:error] [pid 2387] [client 127.0.0.1:40286] AH01215:     from core.db import DBQuery
[Tue Aug 22 19:27:34.203675 2017] [cgi:error] [pid 2387] [client 127.0.0.1:40286] AH01215: ImportError: No module named core.db
[Tue Aug 22 19:27:34.205944 2017] [cgi:error] [pid 2387] [client 127.0.0.1:40286] End of script output before headers: xfc.py
[Tue Aug 22 19:27:40.192979 2017] [cgi:error] [pid 2390] [client 127.0.0.1:40288] AH01215: Traceback (most recent call last):
[Tue Aug 22 19:27:40.193066 2017] [cgi:error] [pid 2390] [client 127.0.0.1:40288] AH01215:   File "/home/debian/server/crm/rootsystem/application/xfc.py", line 15, in <module>
[Tue Aug 22 19:27:40.193100 2017] [cgi:error] [pid 2390] [client 127.0.0.1:40288] AH01215:     m = __import__("modules.{}".format(modulo), fromlist=[controlador])
[Tue Aug 22 19:27:40.193141 2017] [cgi:error] [pid 2390] [client 127.0.0.1:40288] AH01215:   File "/home/debian/server/crm/rootsystem/application/modules/producto.py", line 3, in <module>
[Tue Aug 22 19:27:40.193174 2017] [cgi:error] [pid 2390] [client 127.0.0.1:40288] AH01215:     from core.db import DBQuery
[Tue Aug 22 19:27:40.193192 2017] [cgi:error] [pid 2390] [client 127.0.0.1:40288] AH01215: ImportError: No module named core.db
[Tue Aug 22 19:27:40.195504 2017] [cgi:error] [pid 2390] [client 127.0.0.1:40288] End of script output before headers: xfc.py
[Tue Aug 22 19:27:52.197765 2017] [cgi:error] [pid 2389] [client 127.0.0.1:40290] AH01215: Traceback (most recent call last):
[Tue Aug 22 19:27:52.197839 2017] [cgi:error] [pid 2389] [client 127.0.0.1:40290] AH01215:   File "/home/debian/server/crm/rootsystem/application/xfc.py", line 15, in <module>
[Tue Aug 22 19:27:52.197872 2017] [cgi:error] [pid 2389] [client 127.0.0.1:40290] AH01215:     m = __import__("modules.{}".format(modulo), fromlist=[controlador])
[Tue Aug 22 19:27:52.197914 2017] [cgi:error] [pid 2389] [client 127.0.0.1:40290] AH01215:   File "/home/debian/server/crm/rootsystem/application/modules/producto.py", line 3, in <module>
[Tue Aug 22 19:27:52.197931 2017] [cgi:error] [pid 2389] [client 127.0.0.1:40290] AH01215:     from core.db import DBQuery
[Tue Aug 22 19:27:52.197950 2017] [cgi:error] [pid 2389] [client 127.0.0.1:40290] AH01215: ImportError: No module named core.db
[Tue Aug 22 19:27:52.200226 2017] [cgi:error] [pid 2389] [client 127.0.0.1:40290] End of script output before headers: xfc.py
[Tue Aug 22 19:28:07.693209 2017] [cgi:error] [pid 2386] [client 127.0.0.1:40292] AH01215: Traceback (most recent call last):
[Tue Aug 22 19:28:07.693270 2017] [cgi:error] [pid 2386] [client 127.0.0.1:40292] AH01215:   File "/home/debian/server/crm/rootsystem/application/xfc.py", line 12, in <module>
[Tue Aug 22 19:28:07.693279 2017] [cgi:error] [pid 2386] [client 127.0.0.1:40292] AH01215:     recurso = uri[2]
[Tue Aug 22 19:28:07.693289 2017] [cgi:error] [pid 2386] [client 127.0.0.1:40292] AH01215: IndexError: list index out of range
[Tue Aug 22 19:28:07.694931 2017] [cgi:error] [pid 2386] [client 127.0.0.1:40292] End of script output before headers: xfc.py
[Tue Aug 22 19:29:37.338793 2017] [cgi:error] [pid 2388] [client 127.0.0.1:40302] AH01215: Traceback (most recent call last):
[Tue Aug 22 19:29:37.338855 2017] [cgi:error] [pid 2388] [client 127.0.0.1:40302] AH01215:   File "/home/debian/server/crm/rootsystem/application/xfc.py", line 15, in <module>
[Tue Aug 22 19:29:37.338874 2017] [cgi:error] [pid 2388] [client 127.0.0.1:40302] AH01215:     m = __import__("modules.{}".format(modulo), fromlist=[controlador])
[Tue Aug 22 19:29:37.338895 2017] [cgi:error] [pid 2388] [client 127.0.0.1:40302] AH01215:   File "/home/debian/server/crm/rootsystem/application/modules/producto.py", line 3, in <module>
[Tue Aug 22 19:29:37.338904 2017] [cgi:error] [pid 2388] [client 127.0.0.1:40302] AH01215:     from core.db import DBQuery
[Tue Aug 22 19:29:37.338915 2017] [cgi:error] [pid 2388] [client 127.0.0.1:40302] AH01215: ImportError: No module named core.db
[Tue Aug 22 19:29:37.341930 2017] [cgi:error] [pid 2388] [client 127.0.0.1:40302] End of script output before headers: xfc.py
[Tue Aug 22 19:29:42.989271 2017] [cgi:error] [pid 2387] [client 127.0.0.1:40304] AH01215: Traceback (most recent call last):
[Tue Aug 22 19:29:42.989332 2017] [cgi:error] [pid 2387] [client 127.0.0.1:40304] AH01215:   File "/home/debian/server/crm/rootsystem/application/xfc.py", line 15, in <module>
[Tue Aug 22 19:29:42.989350 2017] [cgi:error] [pid 2387] [client 127.0.0.1:40304] AH01215:     m = __import__("modules.{}".format(modulo), fromlist=[controlador])
[Tue Aug 22 19:29:42.989372 2017] [cgi:error] [pid 2387] [client 127.0.0.1:40304] AH01215:   File "/home/debian/server/crm/rootsystem/application/modules/producto.py", line 3, in <module>
[Tue Aug 22 19:29:42.989381 2017] [cgi:error] [pid 2387] [client 127.0.0.1:40304] AH01215:     from core.db import DBQuery
[Tue Aug 22 19:29:42.989391 2017] [cgi:error] [pid 2387] [client 127.0.0.1:40304] AH01215: ImportError: No module named core.db
[Tue Aug 22 19:29:42.991690 2017] [cgi:error] [pid 2387] [client 127.0.0.1:40304] End of script output before headers: xfc.py
[Tue Aug 22 19:29:52.169522 2017] [cgi:error] [pid 2390] [client 127.0.0.1:40306] AH01215: Traceback (most recent call last):
[Tue Aug 22 19:29:52.169584 2017] [cgi:error] [pid 2390] [client 127.0.0.1:40306] AH01215:   File "/home/debian/server/crm/rootsystem/application/xfc.py", line 12, in <module>
[Tue Aug 22 19:29:52.169593 2017] [cgi:error] [pid 2390] [client 127.0.0.1:40306] AH01215:     recurso = uri[2]
[Tue Aug 22 19:29:52.169603 2017] [cgi:error] [pid 2390] [client 127.0.0.1:40306] AH01215: IndexError: list index out of range
[Tue Aug 22 19:29:52.171186 2017] [cgi:error] [pid 2390] [client 127.0.0.1:40306] End of script output before headers: xfc.py
[Tue Aug 22 19:29:56.360616 2017] [cgi:error] [pid 2389] [client 127.0.0.1:40308] AH01215: Traceback (most recent call last):
[Tue Aug 22 19:29:56.360677 2017] [cgi:error] [pid 2389] [client 127.0.0.1:40308] AH01215:   File "/home/debian/server/crm/rootsystem/application/xfc.py", line 12, in <module>
[Tue Aug 22 19:29:56.360685 2017] [cgi:error] [pid 2389] [client 127.0.0.1:40308] AH01215:     recurso = uri[2]
[Tue Aug 22 19:29:56.360695 2017] [cgi:error] [pid 2389] [client 127.0.0.1:40308] AH01215: IndexError: list index out of range
[Tue Aug 22 19:29:56.362308 2017] [cgi:error] [pid 2389] [client 127.0.0.1:40308] End of script output before headers: xfc.py
[Tue Aug 22 19:30:05.297278 2017] [cgi:error] [pid 2386] [client 127.0.0.1:40310] AH01215: Traceback (most recent call last):
[Tue Aug 22 19:30:05.297338 2017] [cgi:error] [pid 2386] [client 127.0.0.1:40310] AH01215:   File "/home/debian/server/crm/rootsystem/application/xfc.py", line 15, in <module>
[Tue Aug 22 19:30:05.297357 2017] [cgi:error] [pid 2386] [client 127.0.0.1:40310] AH01215:     m = __import__("modules.{}".format(modulo), fromlist=[controlador])
[Tue Aug 22 19:30:05.297379 2017] [cgi:error] [pid 2386] [client 127.0.0.1:40310] AH01215:   File "/home/debian/server/crm/rootsystem/application/modules/producto.py", line 3, in <module>
[Tue Aug 22 19:30:05.297388 2017] [cgi:error] [pid 2386] [client 127.0.0.1:40310] AH01215:     from core.db import DBQuery
[Tue Aug 22 19:30:05.297398 2017] [cgi:error] [pid 2386] [client 127.0.0.1:40310] AH01215: ImportError: No module named core.db
[Tue Aug 22 19:30:05.299602 2017] [cgi:error] [pid 2386] [client 127.0.0.1:40310] End of script output before headers: xfc.py
[Wed Aug 23 10:31:32.356526 2017] [cgi:error] [pid 22693] [client 127.0.0.1:37888] AH01215: Traceback (most recent call last):
[Wed Aug 23 10:31:32.388838 2017] [cgi:error] [pid 22693] [client 127.0.0.1:37888] AH01215:   File "/home/debian/server/crm/rootsystem/application/xfc.py", line 12, in <module>
[Wed Aug 23 10:31:32.388860 2017] [cgi:error] [pid 22693] [client 127.0.0.1:37888] AH01215:     recurso = uri[2]
[Wed Aug 23 10:31:32.388872 2017] [cgi:error] [pid 22693] [client 127.0.0.1:37888] AH01215: IndexError: list index out of range
[Wed Aug 23 10:31:32.388906 2017] [cgi:error] [pid 22693] [client 127.0.0.1:37888] End of script output before headers: xfc.py
[Wed Aug 23 10:31:32.708965 2017] [cgi:error] [pid 22694] [client 127.0.0.1:37890] AH01215: Traceback (most recent call last):
[Wed Aug 23 10:31:32.709033 2017] [cgi:error] [pid 22694] [client 127.0.0.1:37890] AH01215:   File "/home/debian/server/crm/rootsystem/application/xfc.py", line 12, in <module>
[Wed Aug 23 10:31:32.709042 2017] [cgi:error] [pid 22694] [client 127.0.0.1:37890] AH01215:     recurso = uri[2]
[Wed Aug 23 10:31:32.709053 2017] [cgi:error] [pid 22694] [client 127.0.0.1:37890] AH01215: IndexError: list index out of range
[Wed Aug 23 10:31:32.711446 2017] [cgi:error] [pid 22694] [client 127.0.0.1:37890] End of script output before headers: xfc.py
[Wed Aug 23 10:31:37.954402 2017] [cgi:error] [pid 22695] [client 127.0.0.1:37892] AH01215: Traceback (most recent call last):
[Wed Aug 23 10:31:37.954486 2017] [cgi:error] [pid 22695] [client 127.0.0.1:37892] AH01215:   File "/home/debian/server/crm/rootsystem/application/xfc.py", line 17, in <module>
[Wed Aug 23 10:31:37.954505 2017] [cgi:error] [pid 22695] [client 127.0.0.1:37892] AH01215:     getattr(c, recurso)()
[Wed Aug 23 10:31:37.954546 2017] [cgi:error] [pid 22695] [client 127.0.0.1:37892] AH01215: AttributeError: 'DomicilioController' object has no attribute ''
[Wed Aug 23 10:31:37.956959 2017] [cgi:error] [pid 22695] [client 127.0.0.1:37892] End of script output before headers: xfc.py
[Wed Aug 23 10:32:03.878637 2017] [cgi:error] [pid 22697] [client 127.0.0.1:37922] AH01215: Traceback (most recent call last):
[Wed Aug 23 10:32:03.878723 2017] [cgi:error] [pid 22697] [client 127.0.0.1:37922] AH01215:   File "/home/debian/server/crm/rootsystem/application/xfc.py", line 16, in <module>
[Wed Aug 23 10:32:03.878741 2017] [cgi:error] [pid 22697] [client 127.0.0.1:37922] AH01215:     c = getattr(m, controlador)()
[Wed Aug 23 10:32:03.878766 2017] [cgi:error] [pid 22697] [client 127.0.0.1:37922] AH01215: AttributeError: 'module' object has no attribute 'Controller'
[Wed Aug 23 10:32:03.880893 2017] [cgi:error] [pid 22697] [client 127.0.0.1:37922] End of script output before headers: xfc.py
[Wed Aug 23 10:32:11.110643 2017] [cgi:error] [pid 22693] [client 127.0.0.1:37924] AH01215: Traceback (most recent call last):
[Wed Aug 23 10:32:11.110720 2017] [cgi:error] [pid 22693] [client 127.0.0.1:37924] AH01215:   File "/home/debian/server/crm/rootsystem/application/xfc.py", line 15, in <module>
[Wed Aug 23 10:32:11.110752 2017] [cgi:error] [pid 22693] [client 127.0.0.1:37924] AH01215:     m = __import__("modules.{}".format(modulo), fromlist=[controlador])
[Wed Aug 23 10:32:11.110789 2017] [cgi:error] [pid 22693] [client 127.0.0.1:37924] AH01215:   File "/home/debian/server/crm/rootsystem/application/modules/producto.py", line 3, in <module>
[Wed Aug 23 10:32:11.110807 2017] [cgi:error] [pid 22693] [client 127.0.0.1:37924] AH01215:     from core.db import DBQuery
[Wed Aug 23 10:32:11.110826 2017] [cgi:error] [pid 22693] [client 127.0.0.1:37924] AH01215: ImportError: No module named core.db
[Wed Aug 23 10:32:11.113538 2017] [cgi:error] [pid 22693] [client 127.0.0.1:37924] End of script output before headers: xfc.py
[Wed Aug 23 10:35:11.039254 2017] [cgi:error] [pid 22694] [client 127.0.0.1:37930] AH01215: Traceback (most recent call last):
[Wed Aug 23 10:35:11.039338 2017] [cgi:error] [pid 22694] [client 127.0.0.1:37930] AH01215:   File "/home/debian/server/crm/rootsystem/application/xfc.py", line 15, in <module>
[Wed Aug 23 10:35:11.039369 2017] [cgi:error] [pid 22694] [client 127.0.0.1:37930] AH01215:     m = __import__("modules.{}".format(modulo), fromlist=[controlador])
[Wed Aug 23 10:35:11.039405 2017] [cgi:error] [pid 22694] [client 127.0.0.1:37930] AH01215:   File "/home/debian/server/crm/rootsystem/application/modules/producto.py", line 3, in <module>
[Wed Aug 23 10:35:11.039423 2017] [cgi:error] [pid 22694] [client 127.0.0.1:37930] AH01215:     from core.db import DBQuery
[Wed Aug 23 10:35:11.039444 2017] [cgi:error] [pid 22694] [client 127.0.0.1:37930] AH01215: ImportError: No module named core.db
[Wed Aug 23 10:35:11.041989 2017] [cgi:error] [pid 22694] [client 127.0.0.1:37930] End of script output before headers: xfc.py
[Wed Aug 23 11:25:16.021154 2017] [cgi:error] [pid 22696] [client 127.0.0.1:38422] AH01215: Traceback (most recent call last):
[Wed Aug 23 11:25:16.074359 2017] [cgi:error] [pid 22696] [client 127.0.0.1:38422] AH01215:   File "/home/debian/server/crm/rootsystem/application/xfc.py", line 12, in <module>
[Wed Aug 23 11:25:16.074383 2017] [cgi:error] [pid 22696] [client 127.0.0.1:38422] AH01215:     recurso = uri[2]
[Wed Aug 23 11:25:16.074394 2017] [cgi:error] [pid 22696] [client 127.0.0.1:38422] AH01215: IndexError: list index out of range
[Wed Aug 23 11:25:16.074416 2017] [cgi:error] [pid 22696] [client 127.0.0.1:38422] End of script output before headers: xfc.py
[Wed Aug 23 11:25:16.902480 2017] [cgi:error] [pid 22697] [client 127.0.0.1:38424] AH01215: Traceback (most recent call last):
[Wed Aug 23 11:25:16.902577 2017] [cgi:error] [pid 22697] [client 127.0.0.1:38424] AH01215:   File "/home/debian/server/crm/rootsystem/application/xfc.py", line 12, in <module>
[Wed Aug 23 11:25:16.902611 2017] [cgi:error] [pid 22697] [client 127.0.0.1:38424] AH01215:     recurso = uri[2]
[Wed Aug 23 11:25:16.902629 2017] [cgi:error] [pid 22697] [client 127.0.0.1:38424] AH01215: IndexError: list index out of range
[Wed Aug 23 11:25:16.904333 2017] [cgi:error] [pid 22697] [client 127.0.0.1:38424] End of script output before headers: xfc.py
[Wed Aug 23 11:31:35.058848 2017] [cgi:error] [pid 14316] [client 127.0.0.1:38468] AH01215: Traceback (most recent call last):
[Wed Aug 23 11:31:35.058940 2017] [cgi:error] [pid 14316] [client 127.0.0.1:38468] AH01215:   File "/home/debian/server/crm/rootsystem/application/xfc.py", line 17, in <module>
[Wed Aug 23 11:31:35.058951 2017] [cgi:error] [pid 14316] [client 127.0.0.1:38468] AH01215:     getattr(c, recurso)()
[Wed Aug 23 11:31:35.058972 2017] [cgi:error] [pid 14316] [client 127.0.0.1:38468] AH01215:   File "/home/debian/server/crm/rootsystem/application/modules/producto.py", line 53, in guardar
[Wed Aug 23 11:31:35.058984 2017] [cgi:error] [pid 14316] [client 127.0.0.1:38468] AH01215:     denominacion = form['denominacion'].value
[Wed Aug 23 11:31:35.058999 2017] [cgi:error] [pid 14316] [client 127.0.0.1:38468] AH01215:   File "/usr/lib/python2.7/cgi.py", line 540, in __getitem__
[Wed Aug 23 11:31:35.360652 2017] [cgi:error] [pid 14316] [client 127.0.0.1:38468] AH01215:     raise KeyError, key
[Wed Aug 23 11:31:35.360688 2017] [cgi:error] [pid 14316] [client 127.0.0.1:38468] AH01215: KeyError
[Wed Aug 23 11:31:35.360698 2017] [cgi:error] [pid 14316] [client 127.0.0.1:38468] AH01215: : 
[Wed Aug 23 11:31:35.360711 2017] [cgi:error] [pid 14316] [client 127.0.0.1:38468] AH01215: 'denominacion'
[Wed Aug 23 11:31:35.364580 2017] [cgi:error] [pid 14316] [client 127.0.0.1:38468] End of script output before headers: xfc.py
[Thu Aug 24 11:57:46.321344 2017] [cgi:error] [pid 1160] [client 127.0.0.1:34610] AH01215: Traceback (most recent call last):
[Thu Aug 24 11:57:46.369544 2017] [cgi:error] [pid 1160] [client 127.0.0.1:34610] AH01215:   File "/home/debian/server/crm/rootsystem/application/xfc.py", line 12, in <module>
[Thu Aug 24 11:57:46.369591 2017] [cgi:error] [pid 1160] [client 127.0.0.1:34610] AH01215:     recurso = uri[2]
[Thu Aug 24 11:57:46.369619 2017] [cgi:error] [pid 1160] [client 127.0.0.1:34610] AH01215: IndexError: list index out of range
[Thu Aug 24 11:57:46.369644 2017] [cgi:error] [pid 1160] [client 127.0.0.1:34610] End of script output before headers: xfc.py
[Thu Aug 24 12:08:50.818190 2017] [cgi:error] [pid 6550] [client 127.0.0.1:34720] AH01215: Traceback (most recent call last):, referer: http://crm.local/producto/agregar
[Thu Aug 24 12:08:50.818278 2017] [cgi:error] [pid 6550] [client 127.0.0.1:34720] AH01215:   File "/home/debian/server/crm/rootsystem/application/xfc.py", line 17, in <module>, referer: http://crm.local/producto/agregar
[Thu Aug 24 12:08:50.818298 2017] [cgi:error] [pid 6550] [client 127.0.0.1:34720] AH01215:     getattr(c, recurso)(), referer: http://crm.local/producto/agregar
[Thu Aug 24 12:08:50.818334 2017] [cgi:error] [pid 6550] [client 127.0.0.1:34720] AH01215:   File "/home/debian/server/crm/rootsystem/application/modules/producto.py", line 53, in guardar, referer: http://crm.local/producto/agregar
[Thu Aug 24 12:08:50.818356 2017] [cgi:error] [pid 6550] [client 127.0.0.1:34720] AH01215:     denominacion = form['denominacion'].value, referer: http://crm.local/producto/agregar
[Thu Aug 24 12:08:50.818384 2017] [cgi:error] [pid 6550] [client 127.0.0.1:34720] AH01215:   File "/usr/lib/python2.7/cgi.py", line 540, in __getitem__, referer: http://crm.local/producto/agregar
[Thu Aug 24 12:08:50.840378 2017] [cgi:error] [pid 6550] [client 127.0.0.1:34720] AH01215:     raise KeyError, key, referer: http://crm.local/producto/agregar
[Thu Aug 24 12:08:50.840417 2017] [cgi:error] [pid 6550] [client 127.0.0.1:34720] AH01215: KeyError: 'denominacion', referer: http://crm.local/producto/agregar
[Thu Aug 24 12:08:50.843590 2017] [cgi:error] [pid 6550] [client 127.0.0.1:34720] End of script output before headers: xfc.py, referer: http://crm.local/producto/agregar
[Thu Aug 24 12:09:04.495614 2017] [cgi:error] [pid 1160] [client 127.0.0.1:34722] AH01215: Traceback (most recent call last):, referer: http://crm.local/producto/agregar
[Thu Aug 24 12:09:04.495692 2017] [cgi:error] [pid 1160] [client 127.0.0.1:34722] AH01215:   File "/home/debian/server/crm/rootsystem/application/xfc.py", line 17, in <module>, referer: http://crm.local/producto/agregar
[Thu Aug 24 12:09:04.495707 2017] [cgi:error] [pid 1160] [client 127.0.0.1:34722] AH01215:     getattr(c, recurso)(), referer: http://crm.local/producto/agregar
[Thu Aug 24 12:09:04.495739 2017] [cgi:error] [pid 1160] [client 127.0.0.1:34722] AH01215:   File "/home/debian/server/crm/rootsystem/application/modules/producto.py", line 59, in guardar, referer: http://crm.local/producto/agregar
[Thu Aug 24 12:09:04.495753 2017] [cgi:error] [pid 1160] [client 127.0.0.1:34722] AH01215:     self.model.insert(), referer: http://crm.local/producto/agregar
[Thu Aug 24 12:09:04.495787 2017] [cgi:error] [pid 1160] [client 127.0.0.1:34722] AH01215:   File "/home/debian/server/crm/rootsystem/application/modules/producto.py", line 20, in insert, referer: http://crm.local/producto/agregar
[Thu Aug 24 12:09:04.495805 2017] [cgi:error] [pid 1160] [client 127.0.0.1:34722] AH01215:     self.producto_id = DBQuery(sql).execute(), referer: http://crm.local/producto/agregar
[Thu Aug 24 12:09:04.495822 2017] [cgi:error] [pid 1160] [client 127.0.0.1:34722] AH01215: TypeError: object() takes no parameters, referer: http://crm.local/producto/agregar
[Thu Aug 24 12:09:04.498540 2017] [cgi:error] [pid 1160] [client 127.0.0.1:34722] End of script output before headers: xfc.py, referer: http://crm.local/producto/agregar
[Thu Aug 24 12:11:11.958153 2017] [cgi:error] [pid 1161] [client 127.0.0.1:34728] AH01215: Traceback (most recent call last):, referer: http://crm.local/producto/agregar
[Thu Aug 24 12:11:11.958239 2017] [cgi:error] [pid 1161] [client 127.0.0.1:34728] AH01215:   File "/home/debian/server/crm/rootsystem/application/xfc.py", line 17, in <module>, referer: http://crm.local/producto/agregar
[Thu Aug 24 12:11:11.958255 2017] [cgi:error] [pid 1161] [client 127.0.0.1:34728] AH01215:     getattr(c, recurso)(), referer: http://crm.local/producto/agregar
[Thu Aug 24 12:11:11.958292 2017] [cgi:error] [pid 1161] [client 127.0.0.1:34728] AH01215:   File "/home/debian/server/crm/rootsystem/application/modules/producto.py", line 59, in guardar, referer: http://crm.local/producto/agregar
[Thu Aug 24 12:11:11.958306 2017] [cgi:error] [pid 1161] [client 127.0.0.1:34728] AH01215:     self.model.insert(), referer: http://crm.local/producto/agregar
[Thu Aug 24 12:11:11.958338 2017] [cgi:error] [pid 1161] [client 127.0.0.1:34728] AH01215:   File "/home/debian/server/crm/rootsystem/application/modules/producto.py", line 20, in insert, referer: http://crm.local/producto/agregar
[Thu Aug 24 12:11:11.958358 2017] [cgi:error] [pid 1161] [client 127.0.0.1:34728] AH01215:     self.producto_id = DBQuery(sql).execute(), referer: http://crm.local/producto/agregar
[Thu Aug 24 12:11:11.958376 2017] [cgi:error] [pid 1161] [client 127.0.0.1:34728] AH01215: TypeError: object() takes no parameters, referer: http://crm.local/producto/agregar
[Thu Aug 24 12:11:11.961107 2017] [cgi:error] [pid 1161] [client 127.0.0.1:34728] End of script output before headers: xfc.py, referer: http://crm.local/producto/agregar
[Fri Aug 25 10:05:25.876369 2017] [cgi:error] [pid 1272] [client 127.0.0.1:58366] malformed header from script 'xfc.py': Bad header: content-type. text/html; chars
[Fri Aug 25 10:05:26.318397 2017] [cgi:error] [pid 1273] [client 127.0.0.1:58368] AH01215: Traceback (most recent call last):
[Fri Aug 25 10:05:26.318527 2017] [cgi:error] [pid 1273] [client 127.0.0.1:58368] AH01215:   File "/home/debian/server/crm/rootsystem/application/xfc.py", line 12, in <module>
[Fri Aug 25 10:05:26.318543 2017] [cgi:error] [pid 1273] [client 127.0.0.1:58368] AH01215:     recurso = uri[2]
[Fri Aug 25 10:05:26.318561 2017] [cgi:error] [pid 1273] [client 127.0.0.1:58368] AH01215: IndexError: list index out of range
[Fri Aug 25 10:05:26.320933 2017] [cgi:error] [pid 1273] [client 127.0.0.1:58368] End of script output before headers: xfc.py
[Fri Aug 25 10:08:19.424713 2017] [cgi:error] [pid 1275] [client 127.0.0.1:58376] AH01215: Traceback (most recent call last):
[Fri Aug 25 10:08:19.424857 2017] [cgi:error] [pid 1275] [client 127.0.0.1:58376] AH01215:   File "/home/debian/server/crm/rootsystem/application/xfc.py", line 17, in <module>
[Fri Aug 25 10:08:19.424877 2017] [cgi:error] [pid 1275] [client 127.0.0.1:58376] AH01215:     getattr(c, recurso)()
[Fri Aug 25 10:08:19.424914 2017] [cgi:error] [pid 1275] [client 127.0.0.1:58376] AH01215:   File "/home/debian/server/crm/rootsystem/application/modules/domicilio.py", line 59, in guardar
[Fri Aug 25 10:08:19.424933 2017] [cgi:error] [pid 1275] [client 127.0.0.1:58376] AH01215:     numero = form['numero'].value
[Fri Aug 25 10:08:19.424962 2017] [cgi:error] [pid 1275] [client 127.0.0.1:58376] AH01215:   File "/usr/lib/python2.7/cgi.py", line 540, in __getitem__
[Fri Aug 25 10:08:19.446568 2017] [cgi:error] [pid 1275] [client 127.0.0.1:58376] AH01215:     raise KeyError, key
[Fri Aug 25 10:08:19.446605 2017] [cgi:error] [pid 1275] [client 127.0.0.1:58376] AH01215: KeyError: 
[Fri Aug 25 10:08:19.446616 2017] [cgi:error] [pid 1275] [client 127.0.0.1:58376] AH01215: 'numero'
[Fri Aug 25 10:08:19.450406 2017] [cgi:error] [pid 1275] [client 127.0.0.1:58376] End of script output before headers: xfc.py
[Fri Aug 25 10:08:26.554343 2017] [cgi:error] [pid 1274] [client 127.0.0.1:58378] malformed header from script 'xfc.py': Bad header: content-type. text/html; chars
[Fri Aug 25 10:08:55.390479 2017] [cgi:error] [pid 1276] [client 127.0.0.1:58382] AH01215: Traceback (most recent call last):
[Fri Aug 25 10:08:55.390590 2017] [cgi:error] [pid 1276] [client 127.0.0.1:58382] AH01215:   File "/home/debian/server/crm/rootsystem/application/xfc.py", line 17, in <module>
[Fri Aug 25 10:08:55.390601 2017] [cgi:error] [pid 1276] [client 127.0.0.1:58382] AH01215:     getattr(c, recurso)()
[Fri Aug 25 10:08:55.390625 2017] [cgi:error] [pid 1276] [client 127.0.0.1:58382] AH01215:   File "/home/debian/server/crm/rootsystem/application/modules/domicilio.py", line 59, in guardar
[Fri Aug 25 10:08:55.390636 2017] [cgi:error] [pid 1276] [client 127.0.0.1:58382] AH01215:     numero = form['numero'].value
[Fri Aug 25 10:08:55.390653 2017] [cgi:error] [pid 1276] [client 127.0.0.1:58382] AH01215:   File "/usr/lib/python2.7/cgi.py", line 540, in __getitem__
[Fri Aug 25 10:08:55.390663 2017] [cgi:error] [pid 1276] [client 127.0.0.1:58382] AH01215:     raise KeyError, key
[Fri Aug 25 10:08:55.390674 2017] [cgi:error] [pid 1276] [client 127.0.0.1:58382] AH01215: KeyError: 'numero'
[Fri Aug 25 10:08:55.393542 2017] [cgi:error] [pid 1276] [client 127.0.0.1:58382] End of script output before headers: xfc.py
[Fri Aug 25 10:10:38.045696 2017] [cgi:error] [pid 31627] [client 127.0.0.1:58388] malformed header from script 'xfc.py': Bad header: content-type. text/html; chars
[Fri Aug 25 10:13:24.307486 2017] [cgi:error] [pid 1273] [client 127.0.0.1:58412] malformed header from script 'xfc.py': Bad header: content-type. text/html; chars
[Fri Aug 25 10:15:18.231853 2017] [cgi:error] [pid 1274] [client 127.0.0.1:58420] AH01215: Traceback (most recent call last):, referer: http://crm.local/domicilio/agregar/
[Fri Aug 25 10:15:18.231936 2017] [cgi:error] [pid 1274] [client 127.0.0.1:58420] AH01215:   File "/home/debian/server/crm/rootsystem/application/xfc.py", line 17, in <module>, referer: http://crm.local/domicilio/agregar/
[Fri Aug 25 10:15:18.231955 2017] [cgi:error] [pid 1274] [client 127.0.0.1:58420] AH01215:     getattr(c, recurso)(), referer: http://crm.local/domicilio/agregar/
[Fri Aug 25 10:15:18.231989 2017] [cgi:error] [pid 1274] [client 127.0.0.1:58420] AH01215:   File "/home/debian/server/crm/rootsystem/application/modules/domicilio.py", line 63, in guardar, referer: http://crm.local/domicilio/agregar/
[Fri Aug 25 10:15:18.232006 2017] [cgi:error] [pid 1274] [client 127.0.0.1:58420] AH01215:     ciudad = form['ciudad'].value, referer: http://crm.local/domicilio/agregar/
[Fri Aug 25 10:15:18.232040 2017] [cgi:error] [pid 1274] [client 127.0.0.1:58420] AH01215:   File "/usr/lib/python2.7/cgi.py", line 540, in __getitem__, referer: http://crm.local/domicilio/agregar/
[Fri Aug 25 10:15:18.232054 2017] [cgi:error] [pid 1274] [client 127.0.0.1:58420] AH01215:     raise KeyError, key, referer: http://crm.local/domicilio/agregar/
[Fri Aug 25 10:15:18.232067 2017] [cgi:error] [pid 1274] [client 127.0.0.1:58420] AH01215: KeyError: 'ciudad', referer: http://crm.local/domicilio/agregar/
[Fri Aug 25 10:15:18.234823 2017] [cgi:error] [pid 1274] [client 127.0.0.1:58420] End of script output before headers: xfc.py, referer: http://crm.local/domicilio/agregar/
[Fri Aug 25 10:28:53.380053 2017] [cgi:error] [pid 1276] [client 127.0.0.1:58438] AH01215: Traceback (most recent call last):, referer: http://crm.local/domicilio/agregar/
[Fri Aug 25 10:28:53.380133 2017] [cgi:error] [pid 1276] [client 127.0.0.1:58438] AH01215:   File "/home/debian/server/crm/rootsystem/application/xfc.py", line 17, in <module>, referer: http://crm.local/domicilio/agregar/
[Fri Aug 25 10:28:53.380152 2017] [cgi:error] [pid 1276] [client 127.0.0.1:58438] AH01215:     getattr(c, recurso)(), referer: http://crm.local/domicilio/agregar/
[Fri Aug 25 10:28:53.380188 2017] [cgi:error] [pid 1276] [client 127.0.0.1:58438] AH01215:   File "/home/debian/server/crm/rootsystem/application/modules/domicilio.py", line 63, in guardar, referer: http://crm.local/domicilio/agregar/
[Fri Aug 25 10:28:53.380208 2017] [cgi:error] [pid 1276] [client 127.0.0.1:58438] AH01215:     ciudad = form['ciudad'].value, referer: http://crm.local/domicilio/agregar/
[Fri Aug 25 10:28:53.380236 2017] [cgi:error] [pid 1276] [client 127.0.0.1:58438] AH01215:   File "/usr/lib/python2.7/cgi.py", line 540, in __getitem__, referer: http://crm.local/domicilio/agregar/
[Fri Aug 25 10:28:53.380254 2017] [cgi:error] [pid 1276] [client 127.0.0.1:58438] AH01215:     raise KeyError, key, referer: http://crm.local/domicilio/agregar/
[Fri Aug 25 10:28:53.380270 2017] [cgi:error] [pid 1276] [client 127.0.0.1:58438] AH01215: KeyError: 'ciudad', referer: http://crm.local/domicilio/agregar/
[Fri Aug 25 10:28:53.383496 2017] [cgi:error] [pid 1276] [client 127.0.0.1:58438] End of script output before headers: xfc.py, referer: http://crm.local/domicilio/agregar/
[Fri Aug 25 10:36:51.184588 2017] [cgi:error] [pid 31627] [client 127.0.0.1:58496] AH01215: Traceback (most recent call last):, referer: http://crm.local/domicilio/agregar/
[Fri Aug 25 10:36:51.184669 2017] [cgi:error] [pid 31627] [client 127.0.0.1:58496] AH01215:   File "/home/debian/server/crm/rootsystem/application/xfc.py", line 17, in <module>, referer: http://crm.local/domicilio/agregar/
[Fri Aug 25 10:36:51.184687 2017] [cgi:error] [pid 31627] [client 127.0.0.1:58496] AH01215:     getattr(c, recurso)(), referer: http://crm.local/domicilio/agregar/
[Fri Aug 25 10:36:51.184725 2017] [cgi:error] [pid 31627] [client 127.0.0.1:58496] AH01215:   File "/home/debian/server/crm/rootsystem/application/modules/domicilio.py", line 63, in guardar, referer: http://crm.local/domicilio/agregar/
[Fri Aug 25 10:36:51.184745 2017] [cgi:error] [pid 31627] [client 127.0.0.1:58496] AH01215:     ciudad = form['ciudad'].value, referer: http://crm.local/domicilio/agregar/
[Fri Aug 25 10:36:51.184768 2017] [cgi:error] [pid 31627] [client 127.0.0.1:58496] AH01215:   File "/usr/lib/python2.7/cgi.py", line 540, in __getitem__, referer: http://crm.local/domicilio/agregar/
[Fri Aug 25 10:36:51.184784 2017] [cgi:error] [pid 31627] [client 127.0.0.1:58496] AH01215:     raise KeyError, key, referer: http://crm.local/domicilio/agregar/
[Fri Aug 25 10:36:51.184796 2017] [cgi:error] [pid 31627] [client 127.0.0.1:58496] AH01215: KeyError: 'ciudad', referer: http://crm.local/domicilio/agregar/
[Fri Aug 25 10:36:51.187727 2017] [cgi:error] [pid 31627] [client 127.0.0.1:58496] End of script output before headers: xfc.py, referer: http://crm.local/domicilio/agregar/
[Fri Aug 25 10:42:44.555603 2017] [cgi:error] [pid 1272] [client 127.0.0.1:58578] AH01215: Traceback (most recent call last):, referer: http://crm.local/domicilio/agregar/
[Fri Aug 25 10:42:44.555693 2017] [cgi:error] [pid 1272] [client 127.0.0.1:58578] AH01215:   File "/home/debian/server/crm/rootsystem/application/xfc.py", line 17, in <module>, referer: http://crm.local/domicilio/agregar/
[Fri Aug 25 10:42:44.555712 2017] [cgi:error] [pid 1272] [client 127.0.0.1:58578] AH01215:     getattr(c, recurso)(), referer: http://crm.local/domicilio/agregar/
[Fri Aug 25 10:42:44.555749 2017] [cgi:error] [pid 1272] [client 127.0.0.1:58578] AH01215:   File "/home/debian/server/crm/rootsystem/application/modules/domicilio.py", line 63, in guardar, referer: http://crm.local/domicilio/agregar/
[Fri Aug 25 10:42:44.555770 2017] [cgi:error] [pid 1272] [client 127.0.0.1:58578] AH01215:     ciudad = form['ciudad'].value, referer: http://crm.local/domicilio/agregar/
[Fri Aug 25 10:42:44.555797 2017] [cgi:error] [pid 1272] [client 127.0.0.1:58578] AH01215:   File "/usr/lib/python2.7/cgi.py", line 540, in __getitem__, referer: http://crm.local/domicilio/agregar/
[Fri Aug 25 10:42:44.555814 2017] [cgi:error] [pid 1272] [client 127.0.0.1:58578] AH01215:     raise KeyError, key, referer: http://crm.local/domicilio/agregar/
[Fri Aug 25 10:42:44.555827 2017] [cgi:error] [pid 1272] [client 127.0.0.1:58578] AH01215: KeyError: 'ciudad', referer: http://crm.local/domicilio/agregar/
[Fri Aug 25 10:42:44.558675 2017] [cgi:error] [pid 1272] [client 127.0.0.1:58578] End of script output before headers: xfc.py, referer: http://crm.local/domicilio/agregar/
[Fri Aug 25 10:42:52.854961 2017] [cgi:error] [pid 1273] [client 127.0.0.1:58580] AH01215: Traceback (most recent call last):, referer: http://crm.local/domicilio/agregar/
[Fri Aug 25 10:42:52.855035 2017] [cgi:error] [pid 1273] [client 127.0.0.1:58580] AH01215:   File "/home/debian/server/crm/rootsystem/application/xfc.py", line 17, in <module>, referer: http://crm.local/domicilio/agregar/
[Fri Aug 25 10:42:52.855054 2017] [cgi:error] [pid 1273] [client 127.0.0.1:58580] AH01215:     getattr(c, recurso)(), referer: http://crm.local/domicilio/agregar/
[Fri Aug 25 10:42:52.855088 2017] [cgi:error] [pid 1273] [client 127.0.0.1:58580] AH01215:   File "/home/debian/server/crm/rootsystem/application/modules/domicilio.py", line 63, in guardar, referer: http://crm.local/domicilio/agregar/
[Fri Aug 25 10:42:52.855106 2017] [cgi:error] [pid 1273] [client 127.0.0.1:58580] AH01215:     ciudad = form['ciudad'].value, referer: http://crm.local/domicilio/agregar/
[Fri Aug 25 10:42:52.855129 2017] [cgi:error] [pid 1273] [client 127.0.0.1:58580] AH01215:   File "/usr/lib/python2.7/cgi.py", line 540, in __getitem__, referer: http://crm.local/domicilio/agregar/
[Fri Aug 25 10:42:52.855141 2017] [cgi:error] [pid 1273] [client 127.0.0.1:58580] AH01215:     raise KeyError, key, referer: http://crm.local/domicilio/agregar/
[Fri Aug 25 10:42:52.855153 2017] [cgi:error] [pid 1273] [client 127.0.0.1:58580] AH01215: KeyError: 'ciudad', referer: http://crm.local/domicilio/agregar/
[Fri Aug 25 10:42:52.857925 2017] [cgi:error] [pid 1273] [client 127.0.0.1:58580] End of script output before headers: xfc.py, referer: http://crm.local/domicilio/agregar/
[Fri Aug 25 10:45:27.857054 2017] [cgi:error] [pid 1275] [client 127.0.0.1:58584] AH01215: Traceback (most recent call last):, referer: http://crm.local/domicilio/agregar/
[Fri Aug 25 10:45:27.857147 2017] [cgi:error] [pid 1275] [client 127.0.0.1:58584] AH01215:   File "/home/debian/server/crm/rootsystem/application/xfc.py", line 17, in <module>, referer: http://crm.local/domicilio/agregar/
[Fri Aug 25 10:45:27.857167 2017] [cgi:error] [pid 1275] [client 127.0.0.1:58584] AH01215:     getattr(c, recurso)(), referer: http://crm.local/domicilio/agregar/
[Fri Aug 25 10:45:27.857204 2017] [cgi:error] [pid 1275] [client 127.0.0.1:58584] AH01215:   File "/home/debian/server/crm/rootsystem/application/modules/domicilio.py", line 63, in guardar, referer: http://crm.local/domicilio/agregar/
[Fri Aug 25 10:45:27.857235 2017] [cgi:error] [pid 1275] [client 127.0.0.1:58584] AH01215:     ciudad = form['ciudad'].value, referer: http://crm.local/domicilio/agregar/
[Fri Aug 25 10:45:27.857261 2017] [cgi:error] [pid 1275] [client 127.0.0.1:58584] AH01215:   File "/usr/lib/python2.7/cgi.py", line 540, in __getitem__, referer: http://crm.local/domicilio/agregar/
[Fri Aug 25 10:45:27.857275 2017] [cgi:error] [pid 1275] [client 127.0.0.1:58584] AH01215:     raise KeyError, key, referer: http://crm.local/domicilio/agregar/
[Fri Aug 25 10:45:27.857287 2017] [cgi:error] [pid 1275] [client 127.0.0.1:58584] AH01215: KeyError: 'ciudad', referer: http://crm.local/domicilio/agregar/
[Fri Aug 25 10:45:27.861404 2017] [cgi:error] [pid 1275] [client 127.0.0.1:58584] End of script output before headers: xfc.py, referer: http://crm.local/domicilio/agregar/
[Fri Aug 25 10:54:50.711056 2017] [cgi:error] [pid 1274] [client 127.0.0.1:58600] AH01215: Traceback (most recent call last):, referer: http://crm.local/domicilio/agregar/
[Fri Aug 25 10:54:50.711143 2017] [cgi:error] [pid 1274] [client 127.0.0.1:58600] AH01215:   File "/home/debian/server/crm/rootsystem/application/xfc.py", line 17, in <module>, referer: http://crm.local/domicilio/agregar/
[Fri Aug 25 10:54:50.711161 2017] [cgi:error] [pid 1274] [client 127.0.0.1:58600] AH01215:     getattr(c, recurso)(), referer: http://crm.local/domicilio/agregar/
[Fri Aug 25 10:54:50.711201 2017] [cgi:error] [pid 1274] [client 127.0.0.1:58600] AH01215:   File "/home/debian/server/crm/rootsystem/application/modules/domicilio.py", line 63, in guardar, referer: http://crm.local/domicilio/agregar/
[Fri Aug 25 10:54:50.711221 2017] [cgi:error] [pid 1274] [client 127.0.0.1:58600] AH01215:     ciudad = form['ciudad'].value, referer: http://crm.local/domicilio/agregar/
[Fri Aug 25 10:54:50.711247 2017] [cgi:error] [pid 1274] [client 127.0.0.1:58600] AH01215:   File "/usr/lib/python2.7/cgi.py", line 540, in __getitem__, referer: http://crm.local/domicilio/agregar/
[Fri Aug 25 10:54:50.711266 2017] [cgi:error] [pid 1274] [client 127.0.0.1:58600] AH01215:     raise KeyError, key, referer: http://crm.local/domicilio/agregar/
[Fri Aug 25 10:54:50.711280 2017] [cgi:error] [pid 1274] [client 127.0.0.1:58600] AH01215: KeyError: 'ciudad', referer: http://crm.local/domicilio/agregar/
[Fri Aug 25 10:54:50.715613 2017] [cgi:error] [pid 1274] [client 127.0.0.1:58600] End of script output before headers: xfc.py, referer: http://crm.local/domicilio/agregar/
[Fri Aug 25 10:54:57.321914 2017] [cgi:error] [pid 1276] [client 127.0.0.1:58602] AH01215: Traceback (most recent call last):, referer: http://crm.local/domicilio/agregar/
[Fri Aug 25 10:54:57.321992 2017] [cgi:error] [pid 1276] [client 127.0.0.1:58602] AH01215:   File "/home/debian/server/crm/rootsystem/application/xfc.py", line 17, in <module>, referer: http://crm.local/domicilio/agregar/
[Fri Aug 25 10:54:57.322011 2017] [cgi:error] [pid 1276] [client 127.0.0.1:58602] AH01215:     getattr(c, recurso)(), referer: http://crm.local/domicilio/agregar/
[Fri Aug 25 10:54:57.322048 2017] [cgi:error] [pid 1276] [client 127.0.0.1:58602] AH01215:   File "/home/debian/server/crm/rootsystem/application/modules/domicilio.py", line 63, in guardar, referer: http://crm.local/domicilio/agregar/
[Fri Aug 25 10:54:57.322066 2017] [cgi:error] [pid 1276] [client 127.0.0.1:58602] AH01215:     ciudad = form['ciudad'].value, referer: http://crm.local/domicilio/agregar/
[Fri Aug 25 10:54:57.322094 2017] [cgi:error] [pid 1276] [client 127.0.0.1:58602] AH01215:   File "/usr/lib/python2.7/cgi.py", line 540, in __getitem__, referer: http://crm.local/domicilio/agregar/
[Fri Aug 25 10:54:57.322111 2017] [cgi:error] [pid 1276] [client 127.0.0.1:58602] AH01215:     raise KeyError, key, referer: http://crm.local/domicilio/agregar/
[Fri Aug 25 10:54:57.322124 2017] [cgi:error] [pid 1276] [client 127.0.0.1:58602] AH01215: KeyError: 'ciudad', referer: http://crm.local/domicilio/agregar/
[Fri Aug 25 10:54:57.325164 2017] [cgi:error] [pid 1276] [client 127.0.0.1:58602] End of script output before headers: xfc.py, referer: http://crm.local/domicilio/agregar/
[Fri Aug 25 10:55:58.212131 2017] [cgi:error] [pid 31627] [client 127.0.0.1:58604] AH01215: Traceback (most recent call last):, referer: http://crm.local/domicilio/agregar/
[Fri Aug 25 10:55:58.212219 2017] [cgi:error] [pid 31627] [client 127.0.0.1:58604] AH01215:   File "/home/debian/server/crm/rootsystem/application/xfc.py", line 17, in <module>, referer: http://crm.local/domicilio/agregar/
[Fri Aug 25 10:55:58.212237 2017] [cgi:error] [pid 31627] [client 127.0.0.1:58604] AH01215:     getattr(c, recurso)(), referer: http://crm.local/domicilio/agregar/
[Fri Aug 25 10:55:58.212276 2017] [cgi:error] [pid 31627] [client 127.0.0.1:58604] AH01215:   File "/home/debian/server/crm/rootsystem/application/modules/domicilio.py", line 63, in guardar, referer: http://crm.local/domicilio/agregar/
[Fri Aug 25 10:55:58.212297 2017] [cgi:error] [pid 31627] [client 127.0.0.1:58604] AH01215:     ciudad = form['ciudad'].value, referer: http://crm.local/domicilio/agregar/
[Fri Aug 25 10:55:58.212324 2017] [cgi:error] [pid 31627] [client 127.0.0.1:58604] AH01215:   File "/usr/lib/python2.7/cgi.py", line 540, in __getitem__, referer: http://crm.local/domicilio/agregar/
[Fri Aug 25 10:55:58.212339 2017] [cgi:error] [pid 31627] [client 127.0.0.1:58604] AH01215:     raise KeyError, key, referer: http://crm.local/domicilio/agregar/
[Fri Aug 25 10:55:58.212354 2017] [cgi:error] [pid 31627] [client 127.0.0.1:58604] AH01215: KeyError: 'ciudad', referer: http://crm.local/domicilio/agregar/
[Fri Aug 25 10:55:58.215332 2017] [cgi:error] [pid 31627] [client 127.0.0.1:58604] End of script output before headers: xfc.py, referer: http://crm.local/domicilio/agregar/
[Fri Aug 25 10:56:30.017590 2017] [cgi:error] [pid 1273] [client 127.0.0.1:58614] AH01215: Traceback (most recent call last):, referer: http://crm.local/domicilio/agregar/
[Fri Aug 25 10:56:30.017675 2017] [cgi:error] [pid 1273] [client 127.0.0.1:58614] AH01215:   File "/home/debian/server/crm/rootsystem/application/xfc.py", line 17, in <module>, referer: http://crm.local/domicilio/agregar/
[Fri Aug 25 10:56:30.017694 2017] [cgi:error] [pid 1273] [client 127.0.0.1:58614] AH01215:     getattr(c, recurso)(), referer: http://crm.local/domicilio/agregar/
[Fri Aug 25 10:56:30.017731 2017] [cgi:error] [pid 1273] [client 127.0.0.1:58614] AH01215:   File "/home/debian/server/crm/rootsystem/application/modules/domicilio.py", line 73, in guardar, referer: http://crm.local/domicilio/agregar/
[Fri Aug 25 10:56:30.017748 2017] [cgi:error] [pid 1273] [client 127.0.0.1:58614] AH01215:     self.model.insert(), referer: http://crm.local/domicilio/agregar/
[Fri Aug 25 10:56:30.017782 2017] [cgi:error] [pid 1273] [client 127.0.0.1:58614] AH01215:   File "/home/debian/server/crm/rootsystem/application/modules/domicilio.py", line 23, in insert, referer: http://crm.local/domicilio/agregar/
[Fri Aug 25 10:56:30.017805 2017] [cgi:error] [pid 1273] [client 127.0.0.1:58614] AH01215:     self.domicilio_id = DBQuery(sql).execute(), referer: http://crm.local/domicilio/agregar/
[Fri Aug 25 10:56:30.017827 2017] [cgi:error] [pid 1273] [client 127.0.0.1:58614] AH01215: TypeError: object() takes no parameters, referer: http://crm.local/domicilio/agregar/
[Fri Aug 25 10:56:30.021101 2017] [cgi:error] [pid 1273] [client 127.0.0.1:58614] End of script output before headers: xfc.py, referer: http://crm.local/domicilio/agregar/
[Fri Aug 25 10:56:57.525355 2017] [cgi:error] [pid 1275] [client 127.0.0.1:58616] AH01215: Traceback (most recent call last):, referer: http://crm.local/domicilio/agregar/
[Fri Aug 25 10:56:57.525436 2017] [cgi:error] [pid 1275] [client 127.0.0.1:58616] AH01215:   File "/home/debian/server/crm/rootsystem/application/xfc.py", line 17, in <module>, referer: http://crm.local/domicilio/agregar/
[Fri Aug 25 10:56:57.525454 2017] [cgi:error] [pid 1275] [client 127.0.0.1:58616] AH01215:     getattr(c, recurso)(), referer: http://crm.local/domicilio/agregar/
[Fri Aug 25 10:56:57.525488 2017] [cgi:error] [pid 1275] [client 127.0.0.1:58616] AH01215:   File "/home/debian/server/crm/rootsystem/application/modules/domicilio.py", line 73, in guardar, referer: http://crm.local/domicilio/agregar/
[Fri Aug 25 10:56:57.525514 2017] [cgi:error] [pid 1275] [client 127.0.0.1:58616] AH01215:     self.model.insert(), referer: http://crm.local/domicilio/agregar/
[Fri Aug 25 10:56:57.525546 2017] [cgi:error] [pid 1275] [client 127.0.0.1:58616] AH01215:   File "/home/debian/server/crm/rootsystem/application/modules/domicilio.py", line 23, in insert, referer: http://crm.local/domicilio/agregar/
[Fri Aug 25 10:56:57.525566 2017] [cgi:error] [pid 1275] [client 127.0.0.1:58616] AH01215:     self.domicilio_id = DBQuery(sql).execute(), referer: http://crm.local/domicilio/agregar/
[Fri Aug 25 10:56:57.525584 2017] [cgi:error] [pid 1275] [client 127.0.0.1:58616] AH01215: TypeError: object() takes no parameters, referer: http://crm.local/domicilio/agregar/
[Fri Aug 25 10:56:57.528437 2017] [cgi:error] [pid 1275] [client 127.0.0.1:58616] End of script output before headers: xfc.py, referer: http://crm.local/domicilio/agregar/
[Fri Aug 25 11:02:20.094504 2017] [cgi:error] [pid 1274] [client 127.0.0.1:58628] AH01215: Traceback (most recent call last):, referer: http://crm.local/domicilio/agregar/
[Fri Aug 25 11:02:20.094597 2017] [cgi:error] [pid 1274] [client 127.0.0.1:58628] AH01215:   File "/home/debian/server/crm/rootsystem/application/xfc.py", line 17, in <module>, referer: http://crm.local/domicilio/agregar/
[Fri Aug 25 11:02:20.094616 2017] [cgi:error] [pid 1274] [client 127.0.0.1:58628] AH01215:     getattr(c, recurso)(), referer: http://crm.local/domicilio/agregar/
[Fri Aug 25 11:02:20.094652 2017] [cgi:error] [pid 1274] [client 127.0.0.1:58628] AH01215:   File "/home/debian/server/crm/rootsystem/application/modules/domicilio.py", line 73, in guardar, referer: http://crm.local/domicilio/agregar/
[Fri Aug 25 11:02:20.094668 2017] [cgi:error] [pid 1274] [client 127.0.0.1:58628] AH01215:     self.model.insert(), referer: http://crm.local/domicilio/agregar/
[Fri Aug 25 11:02:20.094704 2017] [cgi:error] [pid 1274] [client 127.0.0.1:58628] AH01215:   File "/home/debian/server/crm/rootsystem/application/modules/domicilio.py", line 23, in insert, referer: http://crm.local/domicilio/agregar/
[Fri Aug 25 11:02:20.094727 2017] [cgi:error] [pid 1274] [client 127.0.0.1:58628] AH01215:     self.domicilio_id = DBQuery(sql).execute(), referer: http://crm.local/domicilio/agregar/
[Fri Aug 25 11:02:20.094747 2017] [cgi:error] [pid 1274] [client 127.0.0.1:58628] AH01215: TypeError: object() takes no parameters, referer: http://crm.local/domicilio/agregar/
[Fri Aug 25 11:02:20.097325 2017] [cgi:error] [pid 1274] [client 127.0.0.1:58628] End of script output before headers: xfc.py, referer: http://crm.local/domicilio/agregar/
[Fri Aug 25 11:14:52.386478 2017] [cgi:error] [pid 1276] [client 127.0.0.1:58686] AH01215: Traceback (most recent call last):, referer: http://crm.local/domicilio/agregar/
[Fri Aug 25 11:14:52.386553 2017] [cgi:error] [pid 1276] [client 127.0.0.1:58686] AH01215:   File "/home/debian/server/crm/rootsystem/application/xfc.py", line 17, in <module>, referer: http://crm.local/domicilio/agregar/
[Fri Aug 25 11:14:52.386565 2017] [cgi:error] [pid 1276] [client 127.0.0.1:58686] AH01215:     getattr(c, recurso)(), referer: http://crm.local/domicilio/agregar/
[Fri Aug 25 11:14:52.386594 2017] [cgi:error] [pid 1276] [client 127.0.0.1:58686] AH01215:   File "/home/debian/server/crm/rootsystem/application/modules/domicilio.py", line 73, in guardar, referer: http://crm.local/domicilio/agregar/
[Fri Aug 25 11:14:52.386609 2017] [cgi:error] [pid 1276] [client 127.0.0.1:58686] AH01215:     self.model.insert(), referer: http://crm.local/domicilio/agregar/
[Fri Aug 25 11:14:52.386643 2017] [cgi:error] [pid 1276] [client 127.0.0.1:58686] AH01215:   File "/home/debian/server/crm/rootsystem/application/modules/domicilio.py", line 23, in insert, referer: http://crm.local/domicilio/agregar/
[Fri Aug 25 11:14:52.386668 2017] [cgi:error] [pid 1276] [client 127.0.0.1:58686] AH01215:     self.domicilio_id = DBQuery(sql).execute(), referer: http://crm.local/domicilio/agregar/
[Fri Aug 25 11:14:52.386694 2017] [cgi:error] [pid 1276] [client 127.0.0.1:58686] AH01215: TypeError: object() takes no parameters, referer: http://crm.local/domicilio/agregar/
[Fri Aug 25 11:14:52.390591 2017] [cgi:error] [pid 1276] [client 127.0.0.1:58686] End of script output before headers: xfc.py, referer: http://crm.local/domicilio/agregar/
[Fri Aug 25 11:40:21.118111 2017] [cgi:error] [pid 1272] [client 127.0.0.1:58720] AH01215: Traceback (most recent call last):, referer: http://crm.local/producto/agregar
[Fri Aug 25 11:40:21.118199 2017] [cgi:error] [pid 1272] [client 127.0.0.1:58720] AH01215:   File "/home/debian/server/crm/rootsystem/application/xfc.py", line 17, in <module>, referer: http://crm.local/producto/agregar
[Fri Aug 25 11:40:21.118219 2017] [cgi:error] [pid 1272] [client 127.0.0.1:58720] AH01215:     getattr(c, recurso)(), referer: http://crm.local/producto/agregar
[Fri Aug 25 11:40:21.118258 2017] [cgi:error] [pid 1272] [client 127.0.0.1:58720] AH01215:   File "/home/debian/server/crm/rootsystem/application/modules/producto.py", line 63, in guardar, referer: http://crm.local/producto/agregar
[Fri Aug 25 11:40:21.118275 2017] [cgi:error] [pid 1272] [client 127.0.0.1:58720] AH01215:     self.model.insert(), referer: http://crm.local/producto/agregar
[Fri Aug 25 11:40:21.118313 2017] [cgi:error] [pid 1272] [client 127.0.0.1:58720] AH01215:   File "/home/debian/server/crm/rootsystem/application/modules/producto.py", line 20, in insert, referer: http://crm.local/producto/agregar
[Fri Aug 25 11:40:21.118335 2017] [cgi:error] [pid 1272] [client 127.0.0.1:58720] AH01215:     self.producto_id = DBQuery(sql).execute(), referer: http://crm.local/producto/agregar
[Fri Aug 25 11:40:21.118356 2017] [cgi:error] [pid 1272] [client 127.0.0.1:58720] AH01215: TypeError: object() takes no parameters, referer: http://crm.local/producto/agregar
[Fri Aug 25 11:40:21.121132 2017] [cgi:error] [pid 1272] [client 127.0.0.1:58720] End of script output before headers: xfc.py, referer: http://crm.local/producto/agregar
[Fri Aug 25 14:22:36.940538 2017] [cgi:error] [pid 1272] [client 127.0.0.1:59348] AH01215: Traceback (most recent call last):
[Fri Aug 25 14:22:36.992076 2017] [cgi:error] [pid 1272] [client 127.0.0.1:59348] AH01215:   File "/home/debian/server/crm/rootsystem/application/xfc.py", line 12, in <module>
[Fri Aug 25 14:22:36.992097 2017] [cgi:error] [pid 1272] [client 127.0.0.1:59348] AH01215:     recurso = uri[2]
[Fri Aug 25 14:22:36.992111 2017] [cgi:error] [pid 1272] [client 127.0.0.1:59348] AH01215: IndexError: list index out of range
[Fri Aug 25 14:22:36.992134 2017] [cgi:error] [pid 1272] [client 127.0.0.1:59348] End of script output before headers: xfc.py
[Fri Aug 25 14:25:21.813629 2017] [cgi:error] [pid 1274] [client 127.0.0.1:59372] AH01215: /home/debian/server/crm/rootsystem/application/core/db.py:16: Warning: Out of range value for column 'precio' at row 1, referer: http://crm.local/producto/agregar
[Fri Aug 25 14:25:21.813686 2017] [cgi:error] [pid 1274] [client 127.0.0.1:59372] AH01215:   cursor.execute(self.sql), referer: http://crm.local/producto/agregar
[Fri Aug 25 14:31:11.314364 2017] [cgi:error] [pid 1275] [client 127.0.0.1:59378] AH01215: /home/debian/server/crm/rootsystem/application/core/db.py:16: Warning: Out of range value for column 'precio' at row 1, referer: http://crm.local/producto/agregar
[Fri Aug 25 14:31:11.314422 2017] [cgi:error] [pid 1275] [client 127.0.0.1:59378] AH01215:   cursor.execute(self.sql), referer: http://crm.local/producto/agregar
[Tue Aug 29 15:07:43.286436 2017] [cgi:error] [pid 3783] [client 127.0.0.1:47146] AH01215: Traceback (most recent call last):
[Tue Aug 29 15:07:43.318105 2017] [cgi:error] [pid 3783] [client 127.0.0.1:47146] AH01215:   File "/home/debian/server/crm/rootsystem/application/xfc.py", line 17, in <module>
[Tue Aug 29 15:07:43.318127 2017] [cgi:error] [pid 3783] [client 127.0.0.1:47146] AH01215:     getattr(c, recurso)()
[Tue Aug 29 15:07:43.318147 2017] [cgi:error] [pid 3783] [client 127.0.0.1:47146] AH01215: AttributeError: 'DomicilioController' object has no attribute 'ver1'
[Tue Aug 29 15:07:43.342447 2017] [cgi:error] [pid 3783] [client 127.0.0.1:47146] End of script output before headers: xfc.py
[Tue Aug 29 15:07:43.893442 2017] [cgi:error] [pid 3785] [client 127.0.0.1:47148] AH01215: Traceback (most recent call last):
[Tue Aug 29 15:07:43.893547 2017] [cgi:error] [pid 3785] [client 127.0.0.1:47148] AH01215:   File "/home/debian/server/crm/rootsystem/application/xfc.py", line 12, in <module>
[Tue Aug 29 15:07:43.893562 2017] [cgi:error] [pid 3785] [client 127.0.0.1:47148] AH01215:     recurso = uri[2]
[Tue Aug 29 15:07:43.893578 2017] [cgi:error] [pid 3785] [client 127.0.0.1:47148] AH01215: IndexError: list index out of range
[Tue Aug 29 15:07:43.895914 2017] [cgi:error] [pid 3785] [client 127.0.0.1:47148] End of script output before headers: xfc.py
[Tue Aug 29 15:07:51.636673 2017] [cgi:error] [pid 3781] [client 127.0.0.1:47150] AH01215: Traceback (most recent call last):
[Tue Aug 29 15:07:51.636764 2017] [cgi:error] [pid 3781] [client 127.0.0.1:47150] AH01215:   File "/home/debian/server/crm/rootsystem/application/xfc.py", line 17, in <module>
[Tue Aug 29 15:07:51.636780 2017] [cgi:error] [pid 3781] [client 127.0.0.1:47150] AH01215:     getattr(c, recurso)()
[Tue Aug 29 15:07:51.636816 2017] [cgi:error] [pid 3781] [client 127.0.0.1:47150] AH01215:   File "/home/debian/server/crm/rootsystem/application/modules/domicilio.py", line 100, in ver
[Tue Aug 29 15:07:51.636842 2017] [cgi:error] [pid 3781] [client 127.0.0.1:47150] AH01215:     obj_id = int(environ['REQUEST_URI'].split("/")[-1])
[Tue Aug 29 15:07:51.636863 2017] [cgi:error] [pid 3781] [client 127.0.0.1:47150] AH01215: NameError: global name 'environ' is not defined
[Tue Aug 29 15:07:51.640494 2017] [cgi:error] [pid 3781] [client 127.0.0.1:47150] End of script output before headers: xfc.py
[Tue Aug 29 15:09:38.452190 2017] [cgi:error] [pid 3782] [client 127.0.0.1:47156] AH01215: Traceback (most recent call last):
[Tue Aug 29 15:09:38.452281 2017] [cgi:error] [pid 3782] [client 127.0.0.1:47156] AH01215:   File "/home/debian/server/crm/rootsystem/application/xfc.py", line 17, in <module>
[Tue Aug 29 15:09:38.452300 2017] [cgi:error] [pid 3782] [client 127.0.0.1:47156] AH01215:     getattr(c, recurso)()
[Tue Aug 29 15:09:38.452335 2017] [cgi:error] [pid 3782] [client 127.0.0.1:47156] AH01215:   File "/home/debian/server/crm/rootsystem/application/modules/domicilio.py", line 100, in ver
[Tue Aug 29 15:09:38.452362 2017] [cgi:error] [pid 3782] [client 127.0.0.1:47156] AH01215:     obj_id = int(environ['REQUEST_URI'].split("/")[-1])
[Tue Aug 29 15:09:38.452384 2017] [cgi:error] [pid 3782] [client 127.0.0.1:47156] AH01215: NameError: global name 'environ' is not defined
[Tue Aug 29 15:09:38.456418 2017] [cgi:error] [pid 3782] [client 127.0.0.1:47156] End of script output before headers: xfc.py
[Tue Aug 29 15:09:44.350277 2017] [cgi:error] [pid 3784] [client 127.0.0.1:47158] AH01215: Traceback (most recent call last):
[Tue Aug 29 15:09:44.350351 2017] [cgi:error] [pid 3784] [client 127.0.0.1:47158] AH01215:   File "/home/debian/server/crm/rootsystem/application/xfc.py", line 17, in <module>
[Tue Aug 29 15:09:44.350361 2017] [cgi:error] [pid 3784] [client 127.0.0.1:47158] AH01215:     getattr(c, recurso)()
[Tue Aug 29 15:09:44.350383 2017] [cgi:error] [pid 3784] [client 127.0.0.1:47158] AH01215:   File "/home/debian/server/crm/rootsystem/application/modules/domicilio.py", line 100, in ver
[Tue Aug 29 15:09:44.350399 2017] [cgi:error] [pid 3784] [client 127.0.0.1:47158] AH01215:     obj_id = int(environ['REQUEST_URI'].split("/")[-1])
[Tue Aug 29 15:09:44.350412 2017] [cgi:error] [pid 3784] [client 127.0.0.1:47158] AH01215: NameError: global name 'environ' is not defined
[Tue Aug 29 15:09:44.353885 2017] [cgi:error] [pid 3784] [client 127.0.0.1:47158] End of script output before headers: xfc.py
[Tue Aug 29 15:09:48.890585 2017] [cgi:error] [pid 3783] [client 127.0.0.1:47160] AH01215: Traceback (most recent call last):
[Tue Aug 29 15:09:48.890658 2017] [cgi:error] [pid 3783] [client 127.0.0.1:47160] AH01215:   File "/home/debian/server/crm/rootsystem/application/xfc.py", line 17, in <module>
[Tue Aug 29 15:09:48.890687 2017] [cgi:error] [pid 3783] [client 127.0.0.1:47160] AH01215:     getattr(c, recurso)()
[Tue Aug 29 15:09:48.890733 2017] [cgi:error] [pid 3783] [client 127.0.0.1:47160] AH01215:   File "/home/debian/server/crm/rootsystem/application/modules/domicilio.py", line 100, in ver
[Tue Aug 29 15:09:48.890761 2017] [cgi:error] [pid 3783] [client 127.0.0.1:47160] AH01215:     obj_id = int(environ['REQUEST_URI'].split("/")[-1])
[Tue Aug 29 15:09:48.890780 2017] [cgi:error] [pid 3783] [client 127.0.0.1:47160] AH01215: NameError: global name 'environ' is not defined
[Tue Aug 29 15:09:48.894125 2017] [cgi:error] [pid 3783] [client 127.0.0.1:47160] End of script output before headers: xfc.py
[Tue Aug 29 15:16:48.423162 2017] [cgi:error] [pid 3785] [client 127.0.0.1:47202] AH01215: Traceback (most recent call last):
[Tue Aug 29 15:16:48.423241 2017] [cgi:error] [pid 3785] [client 127.0.0.1:47202] AH01215:   File "/home/debian/server/crm/rootsystem/application/xfc.py", line 17, in <module>
[Tue Aug 29 15:16:48.423258 2017] [cgi:error] [pid 3785] [client 127.0.0.1:47202] AH01215:     getattr(c, recurso)()
[Tue Aug 29 15:16:48.423293 2017] [cgi:error] [pid 3785] [client 127.0.0.1:47202] AH01215:   File "/home/debian/server/crm/rootsystem/application/modules/domicilio.py", line 103, in ver
[Tue Aug 29 15:16:48.423312 2017] [cgi:error] [pid 3785] [client 127.0.0.1:47202] AH01215:     self.model.select()
[Tue Aug 29 15:16:48.423347 2017] [cgi:error] [pid 3785] [client 127.0.0.1:47202] AH01215:   File "/home/debian/server/crm/rootsystem/application/modules/domicilio.py", line 37, in select
[Tue Aug 29 15:16:48.423366 2017] [cgi:error] [pid 3785] [client 127.0.0.1:47202] AH01215:     resultado = DBQuery().execute(sql)[0]
[Tue Aug 29 15:16:48.423398 2017] [cgi:error] [pid 3785] [client 127.0.0.1:47202] AH01215:   File "/home/debian/server/crm/rootsystem/application/core/db.py", line 16, in execute
[Tue Aug 29 15:16:48.423414 2017] [cgi:error] [pid 3785] [client 127.0.0.1:47202] AH01215:     cursor.execute(self.sql)
[Tue Aug 29 15:16:48.423447 2017] [cgi:error] [pid 3785] [client 127.0.0.1:47202] AH01215:   File "/usr/lib/python2.7/dist-packages/MySQLdb/cursors.py", line 174, in execute
[Tue Aug 29 15:16:48.453624 2017] [cgi:error] [pid 3785] [client 127.0.0.1:47202] AH01215:     self.errorhandler(self, exc, value)
[Tue Aug 29 15:16:48.453688 2017] [cgi:error] [pid 3785] [client 127.0.0.1:47202] AH01215:   File "/usr/lib/python2.7/dist-packages/MySQLdb/connections.py", line 36, in defaulterrorhandler
[Tue Aug 29 15:16:48.454270 2017] [cgi:error] [pid 3785] [client 127.0.0.1:47202] AH01215:     raise errorclass, errorvalue
[Tue Aug 29 15:16:48.454327 2017] [cgi:error] [pid 3785] [client 127.0.0.1:47202] AH01215: _mysql_exceptions.OperationalError: (1054, "Unknown column 'ciudad' in 'field list'")
[Tue Aug 29 15:16:48.459447 2017] [cgi:error] [pid 3785] [client 127.0.0.1:47202] End of script output before headers: xfc.py
[Tue Aug 29 15:16:48.837370 2017] [cgi:error] [pid 3781] [client 127.0.0.1:47204] AH01215: Traceback (most recent call last):
[Tue Aug 29 15:16:48.838353 2017] [cgi:error] [pid 3781] [client 127.0.0.1:47204] AH01215:   File "/home/debian/server/crm/rootsystem/application/xfc.py", line 12, in <module>
[Tue Aug 29 15:16:48.838388 2017] [cgi:error] [pid 3781] [client 127.0.0.1:47204] AH01215:     recurso = uri[2]
[Tue Aug 29 15:16:48.838407 2017] [cgi:error] [pid 3781] [client 127.0.0.1:47204] AH01215: IndexError: list index out of range
[Tue Aug 29 15:16:48.840017 2017] [cgi:error] [pid 3781] [client 127.0.0.1:47204] End of script output before headers: xfc.py
[Tue Aug 29 15:21:27.437238 2017] [cgi:error] [pid 3782] [client 127.0.0.1:47222] AH01215: Traceback (most recent call last):
[Tue Aug 29 15:21:27.437323 2017] [cgi:error] [pid 3782] [client 127.0.0.1:47222] AH01215:   File "/home/debian/server/crm/rootsystem/application/xfc.py", line 17, in <module>
[Tue Aug 29 15:21:27.437354 2017] [cgi:error] [pid 3782] [client 127.0.0.1:47222] AH01215:     getattr(c, recurso)()
[Tue Aug 29 15:21:27.437393 2017] [cgi:error] [pid 3782] [client 127.0.0.1:47222] AH01215:   File "/home/debian/server/crm/rootsystem/application/modules/domicilio.py", line 103, in ver
[Tue Aug 29 15:21:27.437409 2017] [cgi:error] [pid 3782] [client 127.0.0.1:47222] AH01215:     self.model.select()
[Tue Aug 29 15:21:27.437445 2017] [cgi:error] [pid 3782] [client 127.0.0.1:47222] AH01215:   File "/home/debian/server/crm/rootsystem/application/modules/domicilio.py", line 37, in select
[Tue Aug 29 15:21:27.437465 2017] [cgi:error] [pid 3782] [client 127.0.0.1:47222] AH01215:     resultado = DBQuery().execute(sql)[0]
[Tue Aug 29 15:21:27.437497 2017] [cgi:error] [pid 3782] [client 127.0.0.1:47222] AH01215:   File "/home/debian/server/crm/rootsystem/application/core/db.py", line 16, in execute
[Tue Aug 29 15:21:27.437513 2017] [cgi:error] [pid 3782] [client 127.0.0.1:47222] AH01215:     cursor.execute(self.sql)
[Tue Aug 29 15:21:27.437544 2017] [cgi:error] [pid 3782] [client 127.0.0.1:47222] AH01215:   File "/usr/lib/python2.7/dist-packages/MySQLdb/cursors.py", line 174, in execute
[Tue Aug 29 15:21:27.437563 2017] [cgi:error] [pid 3782] [client 127.0.0.1:47222] AH01215:     self.errorhandler(self, exc, value)
[Tue Aug 29 15:21:27.437600 2017] [cgi:error] [pid 3782] [client 127.0.0.1:47222] AH01215:   File "/usr/lib/python2.7/dist-packages/MySQLdb/connections.py", line 36, in defaulterrorhandler
[Tue Aug 29 15:21:27.437616 2017] [cgi:error] [pid 3782] [client 127.0.0.1:47222] AH01215:     raise errorclass, errorvalue
[Tue Aug 29 15:21:27.437650 2017] [cgi:error] [pid 3782] [client 127.0.0.1:47222] AH01215: _mysql_exceptions.OperationalError: (1054, "Unknown column 'ciudad' in 'field list'")
[Tue Aug 29 15:21:27.441705 2017] [cgi:error] [pid 3782] [client 127.0.0.1:47222] End of script output before headers: xfc.py
[Tue Aug 29 15:42:15.924398 2017] [cgi:error] [pid 30508] [client 127.0.0.1:47278] AH01215: Traceback (most recent call last):
[Tue Aug 29 15:42:15.924490 2017] [cgi:error] [pid 30508] [client 127.0.0.1:47278] AH01215:   File "/home/debian/server/crm/rootsystem/application/xfc.py", line 17, in <module>
[Tue Aug 29 15:42:15.924509 2017] [cgi:error] [pid 30508] [client 127.0.0.1:47278] AH01215:     getattr(c, recurso)()
[Tue Aug 29 15:42:15.924549 2017] [cgi:error] [pid 30508] [client 127.0.0.1:47278] AH01215:   File "/home/debian/server/crm/rootsystem/application/modules/domicilio.py", line 103, in ver
[Tue Aug 29 15:42:15.924569 2017] [cgi:error] [pid 30508] [client 127.0.0.1:47278] AH01215:     self.model.select()
[Tue Aug 29 15:42:15.924606 2017] [cgi:error] [pid 30508] [client 127.0.0.1:47278] AH01215:   File "/home/debian/server/crm/rootsystem/application/modules/domicilio.py", line 37, in select
[Tue Aug 29 15:42:15.924627 2017] [cgi:error] [pid 30508] [client 127.0.0.1:47278] AH01215:     resultado = DBQuery().execute(sql)[0]
[Tue Aug 29 15:42:15.924644 2017] [cgi:error] [pid 30508] [client 127.0.0.1:47278] AH01215: IndexError: tuple index out of range
[Tue Aug 29 15:42:15.928471 2017] [cgi:error] [pid 30508] [client 127.0.0.1:47278] End of script output before headers: xfc.py
[Thu Aug 31 11:03:04.824416 2017] [cgi:error] [pid 4211] [client 127.0.0.1:49340] AH01215: Traceback (most recent call last):
[Thu Aug 31 11:03:04.881734 2017] [cgi:error] [pid 4211] [client 127.0.0.1:49340] AH01215:   File "/home/debian/server/crm/rootsystem/application/xfc.py", line 12, in <module>
[Thu Aug 31 11:03:04.881755 2017] [cgi:error] [pid 4211] [client 127.0.0.1:49340] AH01215:     recurso = uri[2]
[Thu Aug 31 11:03:04.881767 2017] [cgi:error] [pid 4211] [client 127.0.0.1:49340] AH01215: IndexError: list index out of range
[Thu Aug 31 11:03:04.881785 2017] [cgi:error] [pid 4211] [client 127.0.0.1:49340] End of script output before headers: xfc.py
[Thu Aug 31 11:50:23.820755 2017] [cgi:error] [pid 4213] [client 127.0.0.1:49532] AH01215: Traceback (most recent call last):
[Thu Aug 31 11:50:23.820818 2017] [cgi:error] [pid 4213] [client 127.0.0.1:49532] AH01215:   File "/home/debian/server/crm/rootsystem/application/xfc.py", line 17, in <module>
[Thu Aug 31 11:50:23.820839 2017] [cgi:error] [pid 4213] [client 127.0.0.1:49532] AH01215:     getattr(c, recurso)()
[Thu Aug 31 11:50:23.820860 2017] [cgi:error] [pid 4213] [client 127.0.0.1:49532] AH01215:   File "/home/debian/server/crm/rootsystem/application/modules/producto.py", line 85, in ver
[Thu Aug 31 11:50:23.820867 2017] [cgi:error] [pid 4213] [client 127.0.0.1:49532] AH01215:     self.model.select()
[Thu Aug 31 11:50:23.820888 2017] [cgi:error] [pid 4213] [client 127.0.0.1:49532] AH01215:   File "/home/debian/server/crm/rootsystem/application/modules/producto.py", line 33, in select
[Thu Aug 31 11:50:23.820899 2017] [cgi:error] [pid 4213] [client 127.0.0.1:49532] AH01215:     resultado = DBQuery().execute(sql)[0]
[Thu Aug 31 11:50:23.820918 2017] [cgi:error] [pid 4213] [client 127.0.0.1:49532] AH01215:   File "/home/debian/server/crm/rootsystem/application/core/db.py", line 16, in execute
[Thu Aug 31 11:50:23.820926 2017] [cgi:error] [pid 4213] [client 127.0.0.1:49532] AH01215:     cursor.execute(self.sql)
[Thu Aug 31 11:50:23.820945 2017] [cgi:error] [pid 4213] [client 127.0.0.1:49532] AH01215:   File "/usr/lib/python2.7/dist-packages/MySQLdb/cursors.py", line 174, in execute
[Thu Aug 31 11:50:23.855493 2017] [cgi:error] [pid 4213] [client 127.0.0.1:49532] AH01215:     self.errorhandler(self, exc, value)
[Thu Aug 31 11:50:23.855537 2017] [cgi:error] [pid 4213] [client 127.0.0.1:49532] AH01215:   File "/usr/lib/python2.7/dist-packages/MySQLdb/connections.py", line 36, in defaulterrorhandler
[Thu Aug 31 11:50:23.855714 2017] [cgi:error] [pid 4213] [client 127.0.0.1:49532] AH01215:     raise errorclass, errorvalue
[Thu Aug 31 11:50:23.855745 2017] [cgi:error] [pid 4213] [client 127.0.0.1:49532] AH01215: _mysql_exceptions.OperationalError
[Thu Aug 31 11:50:23.855752 2017] [cgi:error] [pid 4213] [client 127.0.0.1:49532] AH01215: : 
[Thu Aug 31 11:50:23.855771 2017] [cgi:error] [pid 4213] [client 127.0.0.1:49532] AH01215: (1054, "Unknown column 'producto' in 'field list'")
[Thu Aug 31 11:50:23.859678 2017] [cgi:error] [pid 4213] [client 127.0.0.1:49532] End of script output before headers: xfc.py
[Thu Aug 31 11:52:25.345666 2017] [cgi:error] [pid 4214] [client 127.0.0.1:49534] AH01215: Traceback (most recent call last):
[Thu Aug 31 11:52:25.345748 2017] [cgi:error] [pid 4214] [client 127.0.0.1:49534] AH01215:   File "/home/debian/server/crm/rootsystem/application/xfc.py", line 17, in <module>
[Thu Aug 31 11:52:25.345766 2017] [cgi:error] [pid 4214] [client 127.0.0.1:49534] AH01215:     getattr(c, recurso)()
[Thu Aug 31 11:52:25.345803 2017] [cgi:error] [pid 4214] [client 127.0.0.1:49534] AH01215:   File "/home/debian/server/crm/rootsystem/application/modules/producto.py", line 88, in ver
[Thu Aug 31 11:52:25.345818 2017] [cgi:error] [pid 4214] [client 127.0.0.1:49534] AH01215:     self.model.select()
[Thu Aug 31 11:52:25.345852 2017] [cgi:error] [pid 4214] [client 127.0.0.1:49534] AH01215:   File "/home/debian/server/crm/rootsystem/application/modules/producto.py", line 33, in select
[Thu Aug 31 11:52:25.345871 2017] [cgi:error] [pid 4214] [client 127.0.0.1:49534] AH01215:     resultado = DBQuery().execute(sql)[0]
[Thu Aug 31 11:52:25.345902 2017] [cgi:error] [pid 4214] [client 127.0.0.1:49534] AH01215:   File "/home/debian/server/crm/rootsystem/application/core/db.py", line 16, in execute
[Thu Aug 31 11:52:25.345918 2017] [cgi:error] [pid 4214] [client 127.0.0.1:49534] AH01215:     cursor.execute(self.sql)
[Thu Aug 31 11:52:25.345949 2017] [cgi:error] [pid 4214] [client 127.0.0.1:49534] AH01215:   File "/usr/lib/python2.7/dist-packages/MySQLdb/cursors.py", line 174, in execute
[Thu Aug 31 11:52:25.345967 2017] [cgi:error] [pid 4214] [client 127.0.0.1:49534] AH01215:     self.errorhandler(self, exc, value)
[Thu Aug 31 11:52:25.346004 2017] [cgi:error] [pid 4214] [client 127.0.0.1:49534] AH01215:   File "/usr/lib/python2.7/dist-packages/MySQLdb/connections.py", line 36, in defaulterrorhandler
[Thu Aug 31 11:52:25.346031 2017] [cgi:error] [pid 4214] [client 127.0.0.1:49534] AH01215:     raise errorclass, errorvalue
[Thu Aug 31 11:52:25.346065 2017] [cgi:error] [pid 4214] [client 127.0.0.1:49534] AH01215: _mysql_exceptions.OperationalError: (1054, "Unknown column 'producto' in 'field list'")
[Thu Aug 31 11:52:25.349674 2017] [cgi:error] [pid 4214] [client 127.0.0.1:49534] End of script output before headers: xfc.py
[Thu Aug 31 11:53:14.994165 2017] [cgi:error] [pid 4211] [client 127.0.0.1:49548] AH01215: Traceback (most recent call last):
[Thu Aug 31 11:53:14.994258 2017] [cgi:error] [pid 4211] [client 127.0.0.1:49548] AH01215:   File "/home/debian/server/crm/rootsystem/application/xfc.py", line 17, in <module>
[Thu Aug 31 11:53:14.994300 2017] [cgi:error] [pid 4211] [client 127.0.0.1:49548] AH01215:     
[Thu Aug 31 11:53:14.994324 2017] [cgi:error] [pid 4211] [client 127.0.0.1:49548] AH01215: getattr(c, recurso)()
[Thu Aug 31 11:53:14.994386 2017] [cgi:error] [pid 4211] [client 127.0.0.1:49548] AH01215:   File "/home/debian/server/crm/rootsystem/application/modules/producto.py", line 88, in ver
[Thu Aug 31 11:53:14.994429 2017] [cgi:error] [pid 4211] [client 127.0.0.1:49548] AH01215:     
[Thu Aug 31 11:53:14.994450 2017] [cgi:error] [pid 4211] [client 127.0.0.1:49548] AH01215: self.model.select()
[Thu Aug 31 11:53:14.994507 2017] [cgi:error] [pid 4211] [client 127.0.0.1:49548] AH01215:   File "/home/debian/server/crm/rootsystem/application/modules/producto.py", line 33, in select
[Thu Aug 31 11:53:14.994539 2017] [cgi:error] [pid 4211] [client 127.0.0.1:49548] AH01215:     
[Thu Aug 31 11:53:14.994575 2017] [cgi:error] [pid 4211] [client 127.0.0.1:49548] AH01215: resultado = DBQuery().execute(sql)[0]
[Thu Aug 31 11:53:14.994632 2017] [cgi:error] [pid 4211] [client 127.0.0.1:49548] AH01215:   File "/home/debian/server/crm/rootsystem/application/core/db.py", line 16, in execute
[Thu Aug 31 11:53:14.994665 2017] [cgi:error] [pid 4211] [client 127.0.0.1:49548] AH01215:     
[Thu Aug 31 11:53:14.994689 2017] [cgi:error] [pid 4211] [client 127.0.0.1:49548] AH01215: cursor.execute(self.sql)
[Thu Aug 31 11:53:14.994741 2017] [cgi:error] [pid 4211] [client 127.0.0.1:49548] AH01215:   File "/usr/lib/python2.7/dist-packages/MySQLdb/cursors.py", line 174, in execute
[Thu Aug 31 11:53:14.994796 2017] [cgi:error] [pid 4211] [client 127.0.0.1:49548] AH01215:     
[Thu Aug 31 11:53:14.994823 2017] [cgi:error] [pid 4211] [client 127.0.0.1:49548] AH01215: self.errorhandler(self, exc, value)
[Thu Aug 31 11:53:14.994881 2017] [cgi:error] [pid 4211] [client 127.0.0.1:49548] AH01215:   File "/usr/lib/python2.7/dist-packages/MySQLdb/connections.py", line 36, in defaulterrorhandler
[Thu Aug 31 11:53:14.994914 2017] [cgi:error] [pid 4211] [client 127.0.0.1:49548] AH01215:     
[Thu Aug 31 11:53:14.994938 2017] [cgi:error] [pid 4211] [client 127.0.0.1:49548] AH01215: raise errorclass, errorvalue
[Thu Aug 31 11:53:14.994971 2017] [cgi:error] [pid 4211] [client 127.0.0.1:49548] AH01215: _mysql_exceptions
[Thu Aug 31 11:53:14.994985 2017] [cgi:error] [pid 4211] [client 127.0.0.1:49548] AH01215: .
[Thu Aug 31 11:53:14.995004 2017] [cgi:error] [pid 4211] [client 127.0.0.1:49548] AH01215: OperationalError
[Thu Aug 31 11:53:14.995028 2017] [cgi:error] [pid 4211] [client 127.0.0.1:49548] AH01215: : 
[Thu Aug 31 11:53:14.995064 2017] [cgi:error] [pid 4211] [client 127.0.0.1:49548] AH01215: (1054, "Unknown column 'producto' in 'field list'")
[Thu Aug 31 11:53:14.995080 2017] [cgi:error] [pid 4211] [client 127.0.0.1:49548] AH01215: 
[Thu Aug 31 11:53:15.000275 2017] [cgi:error] [pid 4211] [client 127.0.0.1:49548] End of script output before headers: xfc.py
[Thu Aug 31 11:54:47.587359 2017] [cgi:error] [pid 4212] [client 127.0.0.1:49566] AH01215: Traceback (most recent call last):
[Thu Aug 31 11:54:47.587424 2017] [cgi:error] [pid 4212] [client 127.0.0.1:49566] AH01215:   File "/home/debian/server/crm/rootsystem/application/xfc.py", line 17, in <module>
[Thu Aug 31 11:54:47.587434 2017] [cgi:error] [pid 4212] [client 127.0.0.1:49566] AH01215:     getattr(c, recurso)()
[Thu Aug 31 11:54:47.587467 2017] [cgi:error] [pid 4212] [client 127.0.0.1:49566] AH01215:   File "/home/debian/server/crm/rootsystem/application/modules/producto.py", line 88, in ver
[Thu Aug 31 11:54:47.587476 2017] [cgi:error] [pid 4212] [client 127.0.0.1:49566] AH01215:     self.model.select()
[Thu Aug 31 11:54:47.587499 2017] [cgi:error] [pid 4212] [client 127.0.0.1:49566] AH01215:   File "/home/debian/server/crm/rootsystem/application/modules/producto.py", line 33, in select
[Thu Aug 31 11:54:47.587511 2017] [cgi:error] [pid 4212] [client 127.0.0.1:49566] AH01215:     resultado = DBQuery().execute(sql)[0]
[Thu Aug 31 11:54:47.587522 2017] [cgi:error] [pid 4212] [client 127.0.0.1:49566] AH01215: IndexError: tuple index out of range
[Thu Aug 31 11:54:47.591371 2017] [cgi:error] [pid 4212] [client 127.0.0.1:49566] End of script output before headers: xfc.py
[Thu Aug 31 11:54:52.348805 2017] [cgi:error] [pid 4213] [client 127.0.0.1:49568] AH01215: Traceback (most recent call last):
[Thu Aug 31 11:54:52.348879 2017] [cgi:error] [pid 4213] [client 127.0.0.1:49568] AH01215:   File "/home/debian/server/crm/rootsystem/application/xfc.py", line 17, in <module>
[Thu Aug 31 11:54:52.348895 2017] [cgi:error] [pid 4213] [client 127.0.0.1:49568] AH01215:     getattr(c, recurso)()
[Thu Aug 31 11:54:52.348929 2017] [cgi:error] [pid 4213] [client 127.0.0.1:49568] AH01215:   File "/home/debian/server/crm/rootsystem/application/modules/producto.py", line 88, in ver
[Thu Aug 31 11:54:52.348942 2017] [cgi:error] [pid 4213] [client 127.0.0.1:49568] AH01215:     self.model.select()
[Thu Aug 31 11:54:52.348977 2017] [cgi:error] [pid 4213] [client 127.0.0.1:49568] AH01215:   File "/home/debian/server/crm/rootsystem/application/modules/producto.py", line 33, in select
[Thu Aug 31 11:54:52.348995 2017] [cgi:error] [pid 4213] [client 127.0.0.1:49568] AH01215:     resultado = DBQuery().execute(sql)[0]
[Thu Aug 31 11:54:52.349012 2017] [cgi:error] [pid 4213] [client 127.0.0.1:49568] AH01215: IndexError: tuple index out of range
[Thu Aug 31 11:54:52.352512 2017] [cgi:error] [pid 4213] [client 127.0.0.1:49568] End of script output before headers: xfc.py
[Thu Aug 31 11:57:21.388789 2017] [cgi:error] [pid 4214] [client 127.0.0.1:49580] AH01215: Traceback (most recent call last):
[Thu Aug 31 11:57:21.388865 2017] [cgi:error] [pid 4214] [client 127.0.0.1:49580] AH01215:   File "/home/debian/server/crm/rootsystem/application/xfc.py", line 17, in <module>
[Thu Aug 31 11:57:21.388884 2017] [cgi:error] [pid 4214] [client 127.0.0.1:49580] AH01215:     getattr(c, recurso)()
[Thu Aug 31 11:57:21.388917 2017] [cgi:error] [pid 4214] [client 127.0.0.1:49580] AH01215:   File "/home/debian/server/crm/rootsystem/application/modules/producto.py", line 88, in ver
[Thu Aug 31 11:57:21.388932 2017] [cgi:error] [pid 4214] [client 127.0.0.1:49580] AH01215:     self.model.select()
[Thu Aug 31 11:57:21.388969 2017] [cgi:error] [pid 4214] [client 127.0.0.1:49580] AH01215:   File "/home/debian/server/crm/rootsystem/application/modules/producto.py", line 33, in select
[Thu Aug 31 11:57:21.388992 2017] [cgi:error] [pid 4214] [client 127.0.0.1:49580] AH01215:     resultado = DBQuery().execute(sql)[0]
[Thu Aug 31 11:57:21.389012 2017] [cgi:error] [pid 4214] [client 127.0.0.1:49580] AH01215: IndexError: tuple index out of range
[Thu Aug 31 11:57:21.392487 2017] [cgi:error] [pid 4214] [client 127.0.0.1:49580] End of script output before headers: xfc.py
[Tue Sep 05 14:33:43.692937 2017] [cgi:error] [pid 1210] [client 127.0.0.1:55600] malformed header from script 'xfc.py': Bad header: <!DOCTYPE html>
[Tue Sep 05 14:33:44.217591 2017] [cgi:error] [pid 1211] [client 127.0.0.1:55602] AH01215: Traceback (most recent call last):
[Tue Sep 05 14:33:44.217727 2017] [cgi:error] [pid 1211] [client 127.0.0.1:55602] AH01215:   File "/home/debian/server/crm/rootsystem/application/xfc.py", line 12, in <module>
[Tue Sep 05 14:33:44.217745 2017] [cgi:error] [pid 1211] [client 127.0.0.1:55602] AH01215:     recurso = uri[2]
[Tue Sep 05 14:33:44.217764 2017] [cgi:error] [pid 1211] [client 127.0.0.1:55602] AH01215: IndexError: list index out of range
[Tue Sep 05 14:33:44.220442 2017] [cgi:error] [pid 1211] [client 127.0.0.1:55602] End of script output before headers: xfc.py
[Tue Sep 05 14:35:19.089420 2017] [cgi:error] [pid 1212] [client 127.0.0.1:55606] malformed header from script 'xfc.py': Bad header: <!DOCTYPE html>
[Tue Sep 05 14:35:45.896098 2017] [cgi:error] [pid 1213] [client 127.0.0.1:55608] malformed header from script 'xfc.py': Bad header: <!DOCTYPE html>
[Tue Sep 05 14:56:30.663773 2017] [cgi:error] [pid 1211] [client 127.0.0.1:55652] AH01215: Traceback (most recent call last):, referer: http://crm.local/producto/editar/4
[Tue Sep 05 14:56:30.663858 2017] [cgi:error] [pid 1211] [client 127.0.0.1:55652] AH01215:   File "/home/debian/server/crm/rootsystem/application/xfc.py", line 17, in <module>, referer: http://crm.local/producto/editar/4
[Tue Sep 05 14:56:30.663877 2017] [cgi:error] [pid 1211] [client 127.0.0.1:55652] AH01215:     getattr(c, recurso)(), referer: http://crm.local/producto/editar/4
[Tue Sep 05 14:56:30.663911 2017] [cgi:error] [pid 1211] [client 127.0.0.1:55652] AH01215:   File "/home/debian/server/crm/rootsystem/application/modules/producto.py", line 122, in actualizar, referer: http://crm.local/producto/editar/4
[Tue Sep 05 14:56:30.663925 2017] [cgi:error] [pid 1211] [client 127.0.0.1:55652] AH01215:     self.model.update(), referer: http://crm.local/producto/editar/4
[Tue Sep 05 14:56:30.663958 2017] [cgi:error] [pid 1211] [client 127.0.0.1:55652] AH01215:   File "/home/debian/server/crm/rootsystem/application/modules/producto.py", line 31, in update, referer: http://crm.local/producto/editar/4
[Tue Sep 05 14:56:30.663972 2017] [cgi:error] [pid 1211] [client 127.0.0.1:55652] AH01215:     DBQuery().execute(sql), referer: http://crm.local/producto/editar/4
[Tue Sep 05 14:56:30.663990 2017] [cgi:error] [pid 1211] [client 127.0.0.1:55652] AH01215: NameError: global name 'sql' is not defined, referer: http://crm.local/producto/editar/4
[Tue Sep 05 14:56:30.668802 2017] [cgi:error] [pid 1211] [client 127.0.0.1:55652] End of script output before headers: xfc.py, referer: http://crm.local/producto/editar/4
[Thu Sep 07 10:47:32.871640 2017] [cgi:error] [pid 1223] [client 127.0.0.1:37986] AH01215: Traceback (most recent call last):
[Thu Sep 07 10:47:32.930179 2017] [cgi:error] [pid 1223] [client 127.0.0.1:37986] AH01215:   File "/home/debian/server/crm/rootsystem/application/xfc.py", line 12, in <module>
[Thu Sep 07 10:47:32.930203 2017] [cgi:error] [pid 1223] [client 127.0.0.1:37986] AH01215:     recurso = uri[2]
[Thu Sep 07 10:47:32.930228 2017] [cgi:error] [pid 1223] [client 127.0.0.1:37986] AH01215: IndexError: list index out of range
[Thu Sep 07 10:47:32.930249 2017] [cgi:error] [pid 1223] [client 127.0.0.1:37986] End of script output before headers: xfc.py
[Thu Sep 07 10:47:50.890729 2017] [cgi:error] [pid 1224] [client 127.0.0.1:37998] AH01215: Traceback (most recent call last):, referer: http://crm.local/domicilio/editar/1
[Thu Sep 07 10:47:50.890872 2017] [cgi:error] [pid 1224] [client 127.0.0.1:37998] AH01215:   File "/home/debian/server/crm/rootsystem/application/xfc.py", line 17, in <module>, referer: http://crm.local/domicilio/editar/1
[Thu Sep 07 10:47:50.890889 2017] [cgi:error] [pid 1224] [client 127.0.0.1:37998] AH01215:     getattr(c, recurso)(), referer: http://crm.local/domicilio/editar/1
[Thu Sep 07 10:47:50.890929 2017] [cgi:error] [pid 1224] [client 127.0.0.1:37998] AH01215:   File "/home/debian/server/crm/rootsystem/application/modules/domicilio.py", line 150, in actualizar, referer: http://crm.local/domicilio/editar/1
[Thu Sep 07 10:47:50.890947 2017] [cgi:error] [pid 1224] [client 127.0.0.1:37998] AH01215:     seef.view.editar(self.model), referer: http://crm.local/domicilio/editar/1
[Thu Sep 07 10:47:50.890969 2017] [cgi:error] [pid 1224] [client 127.0.0.1:37998] AH01215: NameError: global name 'seef' is not defined, referer: http://crm.local/domicilio/editar/1
[Thu Sep 07 10:47:50.898859 2017] [cgi:error] [pid 1224] [client 127.0.0.1:37998] End of script output before headers: xfc.py, referer: http://crm.local/domicilio/editar/1
[Wed Sep 13 16:15:11.382060 2017] [cgi:error] [pid 2334] [client 127.0.0.1:54884] AH01215: Traceback (most recent call last):
[Wed Sep 13 16:15:11.431531 2017] [cgi:error] [pid 2334] [client 127.0.0.1:54884] AH01215:   File "/home/debian/server/crm/rootsystem/application/xfc.py", line 12, in <module>
[Wed Sep 13 16:15:11.431567 2017] [cgi:error] [pid 2334] [client 127.0.0.1:54884] AH01215:     recurso = uri[2]
[Wed Sep 13 16:15:11.431584 2017] [cgi:error] [pid 2334] [client 127.0.0.1:54884] AH01215: IndexError: list index out of range
[Wed Sep 13 16:15:11.431620 2017] [cgi:error] [pid 2334] [client 127.0.0.1:54884] End of script output before headers: xfc.py
[Wed Sep 13 16:15:51.592156 2017] [cgi:error] [pid 2337] [client 127.0.0.1:54902] AH01215: Traceback (most recent call last):
[Wed Sep 13 16:15:51.592251 2017] [cgi:error] [pid 2337] [client 127.0.0.1:54902] AH01215:   File "/home/debian/server/crm/rootsystem/application/xfc.py", line 17, in <module>
[Wed Sep 13 16:15:51.592269 2017] [cgi:error] [pid 2337] [client 127.0.0.1:54902] AH01215:     getattr(c, recurso)()
[Wed Sep 13 16:15:51.592305 2017] [cgi:error] [pid 2337] [client 127.0.0.1:54902] AH01215:   File "/home/debian/server/crm/rootsystem/application/modules/producto.py", line 106, in ver
[Wed Sep 13 16:15:51.592320 2017] [cgi:error] [pid 2337] [client 127.0.0.1:54902] AH01215:     self.model.select()
[Wed Sep 13 16:15:51.592355 2017] [cgi:error] [pid 2337] [client 127.0.0.1:54902] AH01215:   File "/home/debian/server/crm/rootsystem/application/modules/producto.py", line 39, in select
[Wed Sep 13 16:15:51.592375 2017] [cgi:error] [pid 2337] [client 127.0.0.1:54902] AH01215:     resultado = DBQuery().execute(sql)[0]
[Wed Sep 13 16:15:51.592392 2017] [cgi:error] [pid 2337] [client 127.0.0.1:54902] AH01215: IndexError: tuple index out of range
[Wed Sep 13 16:15:51.596165 2017] [cgi:error] [pid 2337] [client 127.0.0.1:54902] End of script output before headers: xfc.py
[Wed Sep 13 16:15:58.684225 2017] [cgi:error] [pid 2338] [client 127.0.0.1:54904] AH01215: Traceback (most recent call last):
[Wed Sep 13 16:15:58.684314 2017] [cgi:error] [pid 2338] [client 127.0.0.1:54904] AH01215:   File "/home/debian/server/crm/rootsystem/application/xfc.py", line 17, in <module>
[Wed Sep 13 16:15:58.684333 2017] [cgi:error] [pid 2338] [client 127.0.0.1:54904] AH01215:     getattr(c, recurso)()
[Wed Sep 13 16:15:58.684367 2017] [cgi:error] [pid 2338] [client 127.0.0.1:54904] AH01215:   File "/home/debian/server/crm/rootsystem/application/modules/producto.py", line 106, in ver
[Wed Sep 13 16:15:58.684382 2017] [cgi:error] [pid 2338] [client 127.0.0.1:54904] AH01215:     self.model.select()
[Wed Sep 13 16:15:58.684418 2017] [cgi:error] [pid 2338] [client 127.0.0.1:54904] AH01215:   File "/home/debian/server/crm/rootsystem/application/modules/producto.py", line 39, in select
[Wed Sep 13 16:15:58.684438 2017] [cgi:error] [pid 2338] [client 127.0.0.1:54904] AH01215:     resultado = DBQuery().execute(sql)[0]
[Wed Sep 13 16:15:58.684456 2017] [cgi:error] [pid 2338] [client 127.0.0.1:54904] AH01215: IndexError: tuple index out of range
[Wed Sep 13 16:15:58.688546 2017] [cgi:error] [pid 2338] [client 127.0.0.1:54904] End of script output before headers: xfc.py
[Wed Sep 13 16:16:21.943953 2017] [cgi:error] [pid 18753] [client 127.0.0.1:54906] AH01215: Traceback (most recent call last):
[Wed Sep 13 16:16:21.944033 2017] [cgi:error] [pid 18753] [client 127.0.0.1:54906] AH01215:   File "/home/debian/server/crm/rootsystem/application/xfc.py", line 17, in <module>
[Wed Sep 13 16:16:21.944049 2017] [cgi:error] [pid 18753] [client 127.0.0.1:54906] AH01215:     getattr(c, recurso)()
[Wed Sep 13 16:16:21.944082 2017] [cgi:error] [pid 18753] [client 127.0.0.1:54906] AH01215:   File "/home/debian/server/crm/rootsystem/application/modules/producto.py", line 106, in ver
[Wed Sep 13 16:16:21.944094 2017] [cgi:error] [pid 18753] [client 127.0.0.1:54906] AH01215:     self.model.select()
[Wed Sep 13 16:16:21.944146 2017] [cgi:error] [pid 18753] [client 127.0.0.1:54906] AH01215:   File "/home/debian/server/crm/rootsystem/application/modules/producto.py", line 39, in select
[Wed Sep 13 16:16:21.944164 2017] [cgi:error] [pid 18753] [client 127.0.0.1:54906] AH01215:     resultado = DBQuery().execute(sql)[0]
[Wed Sep 13 16:16:21.944180 2017] [cgi:error] [pid 18753] [client 127.0.0.1:54906] AH01215: IndexError: tuple index out of range
[Wed Sep 13 16:16:21.948632 2017] [cgi:error] [pid 18753] [client 127.0.0.1:54906] End of script output before headers: xfc.py
[Wed Sep 13 16:16:28.296759 2017] [cgi:error] [pid 2334] [client 127.0.0.1:54908] AH01215: Traceback (most recent call last):
[Wed Sep 13 16:16:28.296839 2017] [cgi:error] [pid 2334] [client 127.0.0.1:54908] AH01215:   File "/home/debian/server/crm/rootsystem/application/xfc.py", line 17, in <module>
[Wed Sep 13 16:16:28.296857 2017] [cgi:error] [pid 2334] [client 127.0.0.1:54908] AH01215:     getattr(c, recurso)()
[Wed Sep 13 16:16:28.296893 2017] [cgi:error] [pid 2334] [client 127.0.0.1:54908] AH01215:   File "/home/debian/server/crm/rootsystem/application/modules/producto.py", line 106, in ver
[Wed Sep 13 16:16:28.296907 2017] [cgi:error] [pid 2334] [client 127.0.0.1:54908] AH01215:     self.model.select()
[Wed Sep 13 16:16:28.296943 2017] [cgi:error] [pid 2334] [client 127.0.0.1:54908] AH01215:   File "/home/debian/server/crm/rootsystem/application/modules/producto.py", line 39, in select
[Wed Sep 13 16:16:28.296963 2017] [cgi:error] [pid 2334] [client 127.0.0.1:54908] AH01215:     resultado = DBQuery().execute(sql)[0]
[Wed Sep 13 16:16:28.296981 2017] [cgi:error] [pid 2334] [client 127.0.0.1:54908] AH01215: IndexError: tuple index out of range
[Wed Sep 13 16:16:28.300893 2017] [cgi:error] [pid 2334] [client 127.0.0.1:54908] End of script output before headers: xfc.py
[Wed Sep 13 16:16:44.312112 2017] [cgi:error] [pid 2335] [client 127.0.0.1:54910] AH01215: Traceback (most recent call last):
[Wed Sep 13 16:16:44.312195 2017] [cgi:error] [pid 2335] [client 127.0.0.1:54910] AH01215:   File "/home/debian/server/crm/rootsystem/application/xfc.py", line 17, in <module>
[Wed Sep 13 16:16:44.312213 2017] [cgi:error] [pid 2335] [client 127.0.0.1:54910] AH01215:     getattr(c, recurso)()
[Wed Sep 13 16:16:44.312248 2017] [cgi:error] [pid 2335] [client 127.0.0.1:54910] AH01215:   File "/home/debian/server/crm/rootsystem/application/modules/producto.py", line 106, in ver
[Wed Sep 13 16:16:44.312263 2017] [cgi:error] [pid 2335] [client 127.0.0.1:54910] AH01215:     self.model.select()
[Wed Sep 13 16:16:44.312299 2017] [cgi:error] [pid 2335] [client 127.0.0.1:54910] AH01215:   File "/home/debian/server/crm/rootsystem/application/modules/producto.py", line 39, in select
[Wed Sep 13 16:16:44.312320 2017] [cgi:error] [pid 2335] [client 127.0.0.1:54910] AH01215:     resultado = DBQuery().execute(sql)[0]
[Wed Sep 13 16:16:44.312338 2017] [cgi:error] [pid 2335] [client 127.0.0.1:54910] AH01215: IndexError: tuple index out of range
[Wed Sep 13 16:16:44.316251 2017] [cgi:error] [pid 2335] [client 127.0.0.1:54910] End of script output before headers: xfc.py
[Wed Sep 13 16:17:33.646146 2017] [cgi:error] [pid 2337] [client 127.0.0.1:54914] AH01215: Traceback (most recent call last):
[Wed Sep 13 16:17:33.646227 2017] [cgi:error] [pid 2337] [client 127.0.0.1:54914] AH01215:   File "/home/debian/server/crm/rootsystem/application/xfc.py", line 17, in <module>
[Wed Sep 13 16:17:33.646245 2017] [cgi:error] [pid 2337] [client 127.0.0.1:54914] AH01215:     getattr(c, recurso)()
[Wed Sep 13 16:17:33.646280 2017] [cgi:error] [pid 2337] [client 127.0.0.1:54914] AH01215:   File "/home/debian/server/crm/rootsystem/application/modules/producto.py", line 106, in ver
[Wed Sep 13 16:17:33.646295 2017] [cgi:error] [pid 2337] [client 127.0.0.1:54914] AH01215:     self.model.select()
[Wed Sep 13 16:17:33.646331 2017] [cgi:error] [pid 2337] [client 127.0.0.1:54914] AH01215:   File "/home/debian/server/crm/rootsystem/application/modules/producto.py", line 39, in select
[Wed Sep 13 16:17:33.646351 2017] [cgi:error] [pid 2337] [client 127.0.0.1:54914] AH01215:     resultado = DBQuery().execute(sql)[0]
[Wed Sep 13 16:17:33.646381 2017] [cgi:error] [pid 2337] [client 127.0.0.1:54914] AH01215: IndexError: tuple index out of range
[Wed Sep 13 16:17:33.650541 2017] [cgi:error] [pid 2337] [client 127.0.0.1:54914] End of script output before headers: xfc.py
[Thu Sep 14 10:36:11.354849 2017] [cgi:error] [pid 1217] [client 127.0.0.1:34016] AH01215: Traceback (most recent call last):
[Thu Sep 14 10:36:11.422936 2017] [cgi:error] [pid 1217] [client 127.0.0.1:34016] AH01215:   File "/home/debian/server/crm/rootsystem/application/xfc.py", line 12, in <module>
[Thu Sep 14 10:36:11.422958 2017] [cgi:error] [pid 1217] [client 127.0.0.1:34016] AH01215:     recurso = uri[2]
[Thu Sep 14 10:36:11.422970 2017] [cgi:error] [pid 1217] [client 127.0.0.1:34016] AH01215: IndexError: list index out of range
[Thu Sep 14 10:36:11.422988 2017] [cgi:error] [pid 1217] [client 127.0.0.1:34016] End of script output before headers: xfc.py
[Thu Sep 14 10:37:33.540463 2017] [cgi:error] [pid 1220] [client 127.0.0.1:34036] AH01215: Traceback (most recent call last):
[Thu Sep 14 10:37:33.540573 2017] [cgi:error] [pid 1220] [client 127.0.0.1:34036] AH01215:   File "/home/debian/server/crm/rootsystem/application/xfc.py", line 17, in <module>
[Thu Sep 14 10:37:33.540584 2017] [cgi:error] [pid 1220] [client 127.0.0.1:34036] AH01215:     getattr(c, recurso)()
[Thu Sep 14 10:37:33.540610 2017] [cgi:error] [pid 1220] [client 127.0.0.1:34036] AH01215:   File "/home/debian/server/crm/rootsystem/application/modules/domicilio.py", line 126, in ver
[Thu Sep 14 10:37:33.540624 2017] [cgi:error] [pid 1220] [client 127.0.0.1:34036] AH01215:     self.model.select()
[Thu Sep 14 10:37:33.540655 2017] [cgi:error] [pid 1220] [client 127.0.0.1:34036] AH01215:   File "/home/debian/server/crm/rootsystem/application/modules/domicilio.py", line 47, in select
[Thu Sep 14 10:37:33.540673 2017] [cgi:error] [pid 1220] [client 127.0.0.1:34036] AH01215:     resultado = DBQuery().execute(sql)[0]
[Thu Sep 14 10:37:33.540690 2017] [cgi:error] [pid 1220] [client 127.0.0.1:34036] AH01215: IndexError: tuple index out of range
[Thu Sep 14 10:37:33.544546 2017] [cgi:error] [pid 1220] [client 127.0.0.1:34036] End of script output before headers: xfc.py
[Thu Sep 14 10:37:36.576358 2017] [cgi:error] [pid 1221] [client 127.0.0.1:34038] AH01215: Traceback (most recent call last):
[Thu Sep 14 10:37:36.576475 2017] [cgi:error] [pid 1221] [client 127.0.0.1:34038] AH01215:   File "/home/debian/server/crm/rootsystem/application/xfc.py", line 17, in <module>
[Thu Sep 14 10:37:36.576490 2017] [cgi:error] [pid 1221] [client 127.0.0.1:34038] AH01215:     getattr(c, recurso)()
[Thu Sep 14 10:37:36.576516 2017] [cgi:error] [pid 1221] [client 127.0.0.1:34038] AH01215:   File "/home/debian/server/crm/rootsystem/application/modules/domicilio.py", line 126, in ver
[Thu Sep 14 10:37:36.576526 2017] [cgi:error] [pid 1221] [client 127.0.0.1:34038] AH01215:     self.model.select()
[Thu Sep 14 10:37:36.576547 2017] [cgi:error] [pid 1221] [client 127.0.0.1:34038] AH01215:   File "/home/debian/server/crm/rootsystem/application/modules/domicilio.py", line 47, in select
[Thu Sep 14 10:37:36.576559 2017] [cgi:error] [pid 1221] [client 127.0.0.1:34038] AH01215:     resultado = DBQuery().execute(sql)[0]
[Thu Sep 14 10:37:36.576569 2017] [cgi:error] [pid 1221] [client 127.0.0.1:34038] AH01215: IndexError: tuple index out of range
[Thu Sep 14 10:37:36.580313 2017] [cgi:error] [pid 1221] [client 127.0.0.1:34038] End of script output before headers: xfc.py
[Thu Sep 14 10:55:45.302812 2017] [cgi:error] [pid 1218] [client 127.0.0.1:34126] AH01215: Traceback (most recent call last):
[Thu Sep 14 10:55:45.302893 2017] [cgi:error] [pid 1218] [client 127.0.0.1:34126] AH01215:   File "/home/debian/server/crm/rootsystem/application/xfc.py", line 17, in <module>
[Thu Sep 14 10:55:45.302910 2017] [cgi:error] [pid 1218] [client 127.0.0.1:34126] AH01215:     getattr(c, recurso)()
[Thu Sep 14 10:55:45.302938 2017] [cgi:error] [pid 1218] [client 127.0.0.1:34126] AH01215:   File "/home/debian/server/crm/rootsystem/application/modules/domicilio.py", line 133, in ver
[Thu Sep 14 10:55:45.302964 2017] [cgi:error] [pid 1218] [client 127.0.0.1:34126] AH01215:     self.model.select()
[Thu Sep 14 10:55:45.302986 2017] [cgi:error] [pid 1218] [client 127.0.0.1:34126] AH01215:   File "/home/debian/server/crm/rootsystem/application/modules/domicilio.py", line 47, in select
[Thu Sep 14 10:55:45.302998 2017] [cgi:error] [pid 1218] [client 127.0.0.1:34126] AH01215:     resultado = DBQuery().execute(sql)[0]
[Thu Sep 14 10:55:45.303008 2017] [cgi:error] [pid 1218] [client 127.0.0.1:34126] AH01215: IndexError: tuple index out of range
[Thu Sep 14 10:55:45.307567 2017] [cgi:error] [pid 1218] [client 127.0.0.1:34126] End of script output before headers: xfc.py
[Thu Sep 14 10:55:58.038769 2017] [cgi:error] [pid 1220] [client 127.0.0.1:34130] AH01215: Traceback (most recent call last):
[Thu Sep 14 10:55:58.038880 2017] [cgi:error] [pid 1220] [client 127.0.0.1:34130] AH01215:   File "/home/debian/server/crm/rootsystem/application/xfc.py", line 17, in <module>
[Thu Sep 14 10:55:58.038925 2017] [cgi:error] [pid 1220] [client 127.0.0.1:34130] AH01215:     getattr(c, recurso)()
[Thu Sep 14 10:55:58.038983 2017] [cgi:error] [pid 1220] [client 127.0.0.1:34130] AH01215:   File "/home/debian/server/crm/rootsystem/application/modules/domicilio.py", line 167, in eliminar
[Thu Sep 14 10:55:58.039003 2017] [cgi:error] [pid 1220] [client 127.0.0.1:34130] AH01215:     self.view.eliminar()
[Thu Sep 14 10:55:58.039039 2017] [cgi:error] [pid 1220] [client 127.0.0.1:34130] AH01215:   File "/home/debian/server/crm/rootsystem/application/modules/domicilio.py", line 95, in eliminar
[Thu Sep 14 10:55:58.039073 2017] [cgi:error] [pid 1220] [client 127.0.0.1:34130] AH01215:     with open("home/debian/server/crm/rootsystem/static/editar_domicilio.html") as f:
[Thu Sep 14 10:55:58.039116 2017] [cgi:error] [pid 1220] [client 127.0.0.1:34130] AH01215: IOError: [Errno 2] No such file or directory: 'home/debian/server/crm/rootsystem/static/editar_domicilio.html'
[Thu Sep 14 10:55:58.043814 2017] [cgi:error] [pid 1220] [client 127.0.0.1:34130] End of script output before headers: xfc.py
[Thu Sep 14 10:56:06.591222 2017] [cgi:error] [pid 1221] [client 127.0.0.1:34132] AH01215: Traceback (most recent call last):
[Thu Sep 14 10:56:06.591299 2017] [cgi:error] [pid 1221] [client 127.0.0.1:34132] AH01215:   File "/home/debian/server/crm/rootsystem/application/xfc.py", line 17, in <module>
[Thu Sep 14 10:56:06.591315 2017] [cgi:error] [pid 1221] [client 127.0.0.1:34132] AH01215:     getattr(c, recurso)()
[Thu Sep 14 10:56:06.591352 2017] [cgi:error] [pid 1221] [client 127.0.0.1:34132] AH01215:   File "/home/debian/server/crm/rootsystem/application/modules/domicilio.py", line 167, in eliminar
[Thu Sep 14 10:56:06.591367 2017] [cgi:error] [pid 1221] [client 127.0.0.1:34132] AH01215:     self.view.eliminar()
[Thu Sep 14 10:56:06.591403 2017] [cgi:error] [pid 1221] [client 127.0.0.1:34132] AH01215:   File "/home/debian/server/crm/rootsystem/application/modules/domicilio.py", line 95, in eliminar
[Thu Sep 14 10:56:06.591438 2017] [cgi:error] [pid 1221] [client 127.0.0.1:34132] AH01215:     with open("home/debian/server/crm/rootsystem/static/editar_domicilio.html") as f:
[Thu Sep 14 10:56:06.591481 2017] [cgi:error] [pid 1221] [client 127.0.0.1:34132] AH01215: IOError: [Errno 2] No such file or directory: 'home/debian/server/crm/rootsystem/static/editar_domicilio.html'
[Thu Sep 14 10:56:06.595184 2017] [cgi:error] [pid 1221] [client 127.0.0.1:34132] End of script output before headers: xfc.py
[Thu Sep 14 10:58:22.849145 2017] [cgi:error] [pid 6995] [client 127.0.0.1:34134] AH01215: Traceback (most recent call last):
[Thu Sep 14 10:58:22.849239 2017] [cgi:error] [pid 6995] [client 127.0.0.1:34134] AH01215:   File "/home/debian/server/crm/rootsystem/application/xfc.py", line 17, in <module>
[Thu Sep 14 10:58:22.849258 2017] [cgi:error] [pid 6995] [client 127.0.0.1:34134] AH01215:     getattr(c, recurso)()
[Thu Sep 14 10:58:22.849296 2017] [cgi:error] [pid 6995] [client 127.0.0.1:34134] AH01215:   File "/home/debian/server/crm/rootsystem/application/modules/domicilio.py", line 167, in eliminar
[Thu Sep 14 10:58:22.849326 2017] [cgi:error] [pid 6995] [client 127.0.0.1:34134] AH01215:     self.view.eliminar()
[Thu Sep 14 10:58:22.849361 2017] [cgi:error] [pid 6995] [client 127.0.0.1:34134] AH01215:   File "/home/debian/server/crm/rootsystem/application/modules/domicilio.py", line 95, in eliminar
[Thu Sep 14 10:58:22.849396 2017] [cgi:error] [pid 6995] [client 127.0.0.1:34134] AH01215:     with open("home/debian/server/crm/rootsystem/static/eliminar_domicilio.html") as f:
[Thu Sep 14 10:58:22.849436 2017] [cgi:error] [pid 6995] [client 127.0.0.1:34134] AH01215: IOError: [Errno 2] No such file or directory: 'home/debian/server/crm/rootsystem/static/eliminar_domicilio.html'
[Thu Sep 14 10:58:22.854608 2017] [cgi:error] [pid 6995] [client 127.0.0.1:34134] End of script output before headers: xfc.py
[Thu Sep 14 11:01:22.288638 2017] [cgi:error] [pid 1217] [client 127.0.0.1:34140] AH01215: Traceback (most recent call last):
[Thu Sep 14 11:01:22.288717 2017] [cgi:error] [pid 1217] [client 127.0.0.1:34140] AH01215:   File "/home/debian/server/crm/rootsystem/application/xfc.py", line 17, in <module>
[Thu Sep 14 11:01:22.288734 2017] [cgi:error] [pid 1217] [client 127.0.0.1:34140] AH01215:     getattr(c, recurso)()
[Thu Sep 14 11:01:22.288767 2017] [cgi:error] [pid 1217] [client 127.0.0.1:34140] AH01215:   File "/home/debian/server/crm/rootsystem/application/modules/domicilio.py", line 133, in ver
[Thu Sep 14 11:01:22.288780 2017] [cgi:error] [pid 1217] [client 127.0.0.1:34140] AH01215:     self.model.select()
[Thu Sep 14 11:01:22.288812 2017] [cgi:error] [pid 1217] [client 127.0.0.1:34140] AH01215:   File "/home/debian/server/crm/rootsystem/application/modules/domicilio.py", line 47, in select
[Thu Sep 14 11:01:22.288830 2017] [cgi:error] [pid 1217] [client 127.0.0.1:34140] AH01215:     resultado = DBQuery().execute(sql)[0]
[Thu Sep 14 11:01:22.288846 2017] [cgi:error] [pid 1217] [client 127.0.0.1:34140] AH01215: IndexError: tuple index out of range
[Thu Sep 14 11:01:22.292728 2017] [cgi:error] [pid 1217] [client 127.0.0.1:34140] End of script output before headers: xfc.py
[Thu Sep 14 11:01:25.193605 2017] [cgi:error] [pid 1218] [client 127.0.0.1:34142] AH01215: Traceback (most recent call last):
[Thu Sep 14 11:01:25.193688 2017] [cgi:error] [pid 1218] [client 127.0.0.1:34142] AH01215:   File "/home/debian/server/crm/rootsystem/application/xfc.py", line 17, in <module>
[Thu Sep 14 11:01:25.193706 2017] [cgi:error] [pid 1218] [client 127.0.0.1:34142] AH01215:     getattr(c, recurso)()
[Thu Sep 14 11:01:25.193746 2017] [cgi:error] [pid 1218] [client 127.0.0.1:34142] AH01215:   File "/home/debian/server/crm/rootsystem/application/modules/domicilio.py", line 133, in ver
[Thu Sep 14 11:01:25.193761 2017] [cgi:error] [pid 1218] [client 127.0.0.1:34142] AH01215:     self.model.select()
[Thu Sep 14 11:01:25.193801 2017] [cgi:error] [pid 1218] [client 127.0.0.1:34142] AH01215:   File "/home/debian/server/crm/rootsystem/application/modules/domicilio.py", line 47, in select
[Thu Sep 14 11:01:25.193823 2017] [cgi:error] [pid 1218] [client 127.0.0.1:34142] AH01215:     resultado = DBQuery().execute(sql)[0]
[Thu Sep 14 11:01:25.193844 2017] [cgi:error] [pid 1218] [client 127.0.0.1:34142] AH01215: IndexError: tuple index out of range
[Thu Sep 14 11:01:25.197637 2017] [cgi:error] [pid 1218] [client 127.0.0.1:34142] End of script output before headers: xfc.py
[Thu Sep 14 11:05:30.836590 2017] [cgi:error] [pid 1219] [client 127.0.0.1:34166] AH01215: Traceback (most recent call last):
[Thu Sep 14 11:05:30.836677 2017] [cgi:error] [pid 1219] [client 127.0.0.1:34166] AH01215:   File "/home/debian/server/crm/rootsystem/application/xfc.py", line 17, in <module>
[Thu Sep 14 11:05:30.836695 2017] [cgi:error] [pid 1219] [client 127.0.0.1:34166] AH01215:     getattr(c, recurso)()
[Thu Sep 14 11:05:30.836732 2017] [cgi:error] [pid 1219] [client 127.0.0.1:34166] AH01215:   File "/home/debian/server/crm/rootsystem/application/modules/domicilio.py", line 167, in eliminar
[Thu Sep 14 11:05:30.836762 2017] [cgi:error] [pid 1219] [client 127.0.0.1:34166] AH01215:     self.view.eliminar()
[Thu Sep 14 11:05:30.836795 2017] [cgi:error] [pid 1219] [client 127.0.0.1:34166] AH01215:   File "/home/debian/server/crm/rootsystem/application/modules/domicilio.py", line 95, in eliminar
[Thu Sep 14 11:05:30.836827 2017] [cgi:error] [pid 1219] [client 127.0.0.1:34166] AH01215:     with open("home/debian/server/crm/rootsystem/static/eliminar_domicilio.html") as f:
[Thu Sep 14 11:05:30.836865 2017] [cgi:error] [pid 1219] [client 127.0.0.1:34166] AH01215: IOError: [Errno 2] No such file or directory: 'home/debian/server/crm/rootsystem/static/eliminar_domicilio.html'
[Thu Sep 14 11:05:30.842217 2017] [cgi:error] [pid 1219] [client 127.0.0.1:34166] End of script output before headers: xfc.py
[Thu Sep 14 11:12:38.108106 2017] [cgi:error] [pid 1217] [client 127.0.0.1:34184] AH01215: Traceback (most recent call last):
[Thu Sep 14 11:12:38.108190 2017] [cgi:error] [pid 1217] [client 127.0.0.1:34184] AH01215:   File "/home/debian/server/crm/rootsystem/application/xfc.py", line 17, in <module>
[Thu Sep 14 11:12:38.108208 2017] [cgi:error] [pid 1217] [client 127.0.0.1:34184] AH01215:     getattr(c, recurso)()
[Thu Sep 14 11:12:38.108246 2017] [cgi:error] [pid 1217] [client 127.0.0.1:34184] AH01215:   File "/home/debian/server/crm/rootsystem/application/modules/producto.py", line 106, in ver
[Thu Sep 14 11:12:38.108261 2017] [cgi:error] [pid 1217] [client 127.0.0.1:34184] AH01215:     self.model.select()
[Thu Sep 14 11:12:38.108297 2017] [cgi:error] [pid 1217] [client 127.0.0.1:34184] AH01215:   File "/home/debian/server/crm/rootsystem/application/modules/producto.py", line 39, in select
[Thu Sep 14 11:12:38.108319 2017] [cgi:error] [pid 1217] [client 127.0.0.1:34184] AH01215:     resultado = DBQuery().execute(sql)[0]
[Thu Sep 14 11:12:38.108337 2017] [cgi:error] [pid 1217] [client 127.0.0.1:34184] AH01215: IndexError: tuple index out of range
[Thu Sep 14 11:12:38.112145 2017] [cgi:error] [pid 1217] [client 127.0.0.1:34184] End of script output before headers: xfc.py
[Thu Sep 14 11:12:41.166160 2017] [cgi:error] [pid 1218] [client 127.0.0.1:34186] AH01215: Traceback (most recent call last):
[Thu Sep 14 11:12:41.166234 2017] [cgi:error] [pid 1218] [client 127.0.0.1:34186] AH01215:   File "/home/debian/server/crm/rootsystem/application/xfc.py", line 17, in <module>
[Thu Sep 14 11:12:41.166251 2017] [cgi:error] [pid 1218] [client 127.0.0.1:34186] AH01215:     getattr(c, recurso)()
[Thu Sep 14 11:12:41.166296 2017] [cgi:error] [pid 1218] [client 127.0.0.1:34186] AH01215:   File "/home/debian/server/crm/rootsystem/application/modules/producto.py", line 106, in ver
[Thu Sep 14 11:12:41.166315 2017] [cgi:error] [pid 1218] [client 127.0.0.1:34186] AH01215:     self.model.select()
[Thu Sep 14 11:12:41.166347 2017] [cgi:error] [pid 1218] [client 127.0.0.1:34186] AH01215:   File "/home/debian/server/crm/rootsystem/application/modules/producto.py", line 39, in select
[Thu Sep 14 11:12:41.166366 2017] [cgi:error] [pid 1218] [client 127.0.0.1:34186] AH01215:     resultado = DBQuery().execute(sql)[0]
[Thu Sep 14 11:12:41.166382 2017] [cgi:error] [pid 1218] [client 127.0.0.1:34186] AH01215: IndexError: tuple index out of range
[Thu Sep 14 11:12:41.170272 2017] [cgi:error] [pid 1218] [client 127.0.0.1:34186] End of script output before headers: xfc.py
[Thu Sep 14 11:12:45.905297 2017] [cgi:error] [pid 1219] [client 127.0.0.1:34188] AH01215: Traceback (most recent call last):
[Thu Sep 14 11:12:45.905370 2017] [cgi:error] [pid 1219] [client 127.0.0.1:34188] AH01215:   File "/home/debian/server/crm/rootsystem/application/xfc.py", line 17, in <module>
[Thu Sep 14 11:12:45.905389 2017] [cgi:error] [pid 1219] [client 127.0.0.1:34188] AH01215:     getattr(c, recurso)()
[Thu Sep 14 11:12:45.905425 2017] [cgi:error] [pid 1219] [client 127.0.0.1:34188] AH01215:   File "/home/debian/server/crm/rootsystem/application/modules/producto.py", line 106, in ver
[Thu Sep 14 11:12:45.905456 2017] [cgi:error] [pid 1219] [client 127.0.0.1:34188] AH01215:     self.model.select()
[Thu Sep 14 11:12:45.905491 2017] [cgi:error] [pid 1219] [client 127.0.0.1:34188] AH01215:   File "/home/debian/server/crm/rootsystem/application/modules/producto.py", line 39, in select
[Thu Sep 14 11:12:45.905512 2017] [cgi:error] [pid 1219] [client 127.0.0.1:34188] AH01215:     resultado = DBQuery().execute(sql)[0]
[Thu Sep 14 11:12:45.905534 2017] [cgi:error] [pid 1219] [client 127.0.0.1:34188] AH01215: IndexError: tuple index out of range
[Thu Sep 14 11:12:45.909945 2017] [cgi:error] [pid 1219] [client 127.0.0.1:34188] End of script output before headers: xfc.py
[Thu Sep 14 11:18:03.030369 2017] [cgi:error] [pid 1221] [client 127.0.0.1:34202] AH01215: Traceback (most recent call last):
[Thu Sep 14 11:18:03.030453 2017] [cgi:error] [pid 1221] [client 127.0.0.1:34202] AH01215:   File "/home/debian/server/crm/rootsystem/application/xfc.py", line 17, in <module>
[Thu Sep 14 11:18:03.030470 2017] [cgi:error] [pid 1221] [client 127.0.0.1:34202] AH01215:     getattr(c, recurso)()
[Thu Sep 14 11:18:03.030511 2017] [cgi:error] [pid 1221] [client 127.0.0.1:34202] AH01215:   File "/home/debian/server/crm/rootsystem/application/modules/producto.py", line 139, in eliminar
[Thu Sep 14 11:18:03.030526 2017] [cgi:error] [pid 1221] [client 127.0.0.1:34202] AH01215:     self.view.eliminar()
[Thu Sep 14 11:18:03.030566 2017] [cgi:error] [pid 1221] [client 127.0.0.1:34202] AH01215:   File "/home/debian/server/crm/rootsystem/application/modules/producto.py", line 84, in eliminar
[Thu Sep 14 11:18:03.030601 2017] [cgi:error] [pid 1221] [client 127.0.0.1:34202] AH01215:     with open("/home/debian/server/rootsystem/static/eliminar_producto.html") as f:
[Thu Sep 14 11:18:03.030646 2017] [cgi:error] [pid 1221] [client 127.0.0.1:34202] AH01215: IOError: [Errno 2] No such file or directory: '/home/debian/server/rootsystem/static/eliminar_producto.html'
[Thu Sep 14 11:18:03.035057 2017] [cgi:error] [pid 1221] [client 127.0.0.1:34202] End of script output before headers: xfc.py
[Thu Sep 14 11:21:17.848171 2017] [cgi:error] [pid 1217] [client 127.0.0.1:34226] AH01215: Traceback (most recent call last):
[Thu Sep 14 11:21:17.848255 2017] [cgi:error] [pid 1217] [client 127.0.0.1:34226] AH01215:   File "/home/debian/server/crm/rootsystem/application/xfc.py", line 17, in <module>
[Thu Sep 14 11:21:17.848273 2017] [cgi:error] [pid 1217] [client 127.0.0.1:34226] AH01215:     getattr(c, recurso)()
[Thu Sep 14 11:21:17.848309 2017] [cgi:error] [pid 1217] [client 127.0.0.1:34226] AH01215:   File "/home/debian/server/crm/rootsystem/application/modules/producto.py", line 113, in ver
[Thu Sep 14 11:21:17.848323 2017] [cgi:error] [pid 1217] [client 127.0.0.1:34226] AH01215:     self.model.select()
[Thu Sep 14 11:21:17.848359 2017] [cgi:error] [pid 1217] [client 127.0.0.1:34226] AH01215:   File "/home/debian/server/crm/rootsystem/application/modules/producto.py", line 39, in select
[Thu Sep 14 11:21:17.848379 2017] [cgi:error] [pid 1217] [client 127.0.0.1:34226] AH01215:     resultado = DBQuery().execute(sql)[0]
[Thu Sep 14 11:21:17.848397 2017] [cgi:error] [pid 1217] [client 127.0.0.1:34226] AH01215: IndexError: tuple index out of range
[Thu Sep 14 11:21:17.852651 2017] [cgi:error] [pid 1217] [client 127.0.0.1:34226] End of script output before headers: xfc.py
[Tue Sep 19 14:48:53.900037 2017] [cgi:error] [pid 873] [client 127.0.0.1:59480] AH01215: Traceback (most recent call last):
[Tue Sep 19 14:48:53.951266 2017] [cgi:error] [pid 873] [client 127.0.0.1:59480] AH01215:   File "/home/debian/server/crm/rootsystem/application/xfc.py", line 12, in <module>
[Tue Sep 19 14:48:53.951288 2017] [cgi:error] [pid 873] [client 127.0.0.1:59480] AH01215:     recurso = uri[2]
[Tue Sep 19 14:48:53.951300 2017] [cgi:error] [pid 873] [client 127.0.0.1:59480] AH01215: IndexError: list index out of range
[Tue Sep 19 14:48:53.951324 2017] [cgi:error] [pid 873] [client 127.0.0.1:59480] End of script output before headers: xfc.py
[Thu Sep 21 11:22:25.997200 2017] [cgi:error] [pid 3019] [client 127.0.0.1:38102] AH01215: Traceback (most recent call last):
[Thu Sep 21 11:22:26.043637 2017] [cgi:error] [pid 3019] [client 127.0.0.1:38102] AH01215:   File "/home/debian/server/crm/rootsystem/application/xfc.py", line 16, in <module>
[Thu Sep 21 11:22:26.043669 2017] [cgi:error] [pid 3019] [client 127.0.0.1:38102] AH01215:     c = getattr(m, controlador)()
[Thu Sep 21 11:22:26.043697 2017] [cgi:error] [pid 3019] [client 127.0.0.1:38102] AH01215: AttributeError: 'module' object has no attribute 'DatodecontactoController'
[Thu Sep 21 11:22:26.043734 2017] [cgi:error] [pid 3019] [client 127.0.0.1:38102] End of script output before headers: xfc.py
[Thu Sep 21 11:22:26.425663 2017] [cgi:error] [pid 3020] [client 127.0.0.1:38104] AH01215: Traceback (most recent call last):
[Thu Sep 21 11:22:26.425744 2017] [cgi:error] [pid 3020] [client 127.0.0.1:38104] AH01215:   File "/home/debian/server/crm/rootsystem/application/xfc.py", line 12, in <module>
[Thu Sep 21 11:22:26.425759 2017] [cgi:error] [pid 3020] [client 127.0.0.1:38104] AH01215:     recurso = uri[2]
[Thu Sep 21 11:22:26.425778 2017] [cgi:error] [pid 3020] [client 127.0.0.1:38104] AH01215: IndexError: list index out of range
[Thu Sep 21 11:22:26.427474 2017] [cgi:error] [pid 3020] [client 127.0.0.1:38104] End of script output before headers: xfc.py
[Thu Sep 21 11:23:39.772354 2017] [cgi:error] [pid 3021] [client 127.0.0.1:38106] AH01215: Traceback (most recent call last):
[Thu Sep 21 11:23:39.772442 2017] [cgi:error] [pid 3021] [client 127.0.0.1:38106] AH01215:   File "/home/debian/server/crm/rootsystem/application/xfc.py", line 15, in <module>
[Thu Sep 21 11:23:39.772468 2017] [cgi:error] [pid 3021] [client 127.0.0.1:38106] AH01215:     m = __import__("modules.{}".format(modulo), fromlist=[controlador])
[Thu Sep 21 11:23:39.772501 2017] [cgi:error] [pid 3021] [client 127.0.0.1:38106] AH01215:   File "/home/debian/server/crm/rootsystem/application/modules/datodecontacto.py", line 20
[Thu Sep 21 11:23:39.772524 2017] [cgi:error] [pid 3021] [client 127.0.0.1:38106] AH01215:     self.datodecontacto_id = DBQuery().execute(sql)
[Thu Sep 21 11:23:39.772531 2017] [cgi:error] [pid 3021] [client 127.0.0.1:38106] AH01215:     ^
[Thu Sep 21 11:23:39.772547 2017] [cgi:error] [pid 3021] [client 127.0.0.1:38106] AH01215: IndentationError: unexpected indent
[Thu Sep 21 11:23:39.774460 2017] [cgi:error] [pid 3021] [client 127.0.0.1:38106] End of script output before headers: xfc.py
[Thu Sep 21 11:25:59.013613 2017] [cgi:error] [pid 3017] [client 127.0.0.1:38108] AH01215: Traceback (most recent call last):
[Thu Sep 21 11:25:59.013706 2017] [cgi:error] [pid 3017] [client 127.0.0.1:38108] AH01215:   File "/home/debian/server/crm/rootsystem/application/xfc.py", line 16, in <module>
[Thu Sep 21 11:25:59.013731 2017] [cgi:error] [pid 3017] [client 127.0.0.1:38108] AH01215:     c = getattr(m, controlador)()
[Thu Sep 21 11:25:59.013765 2017] [cgi:error] [pid 3017] [client 127.0.0.1:38108] AH01215: AttributeError: 'module' object has no attribute 'DatodecontactoController'
[Thu Sep 21 11:25:59.016649 2017] [cgi:error] [pid 3017] [client 127.0.0.1:38108] End of script output before headers: xfc.py
[Thu Sep 21 11:42:59.363546 2017] [cgi:error] [pid 3019] [client 127.0.0.1:38134] AH01215: Traceback (most recent call last):, referer: http://crm.local/datodecontacto/agregar
[Thu Sep 21 11:42:59.363621 2017] [cgi:error] [pid 3019] [client 127.0.0.1:38134] AH01215:   File "/home/debian/server/crm/rootsystem/application/xfc.py", line 17, in <module>, referer: http://crm.local/datodecontacto/agregar
[Thu Sep 21 11:42:59.363639 2017] [cgi:error] [pid 3019] [client 127.0.0.1:38134] AH01215:     getattr(c, recurso)(), referer: http://crm.local/datodecontacto/agregar
[Thu Sep 21 11:42:59.363673 2017] [cgi:error] [pid 3019] [client 127.0.0.1:38134] AH01215:   File "/home/debian/server/crm/rootsystem/application/modules/producto.py", line 102, in guardar, referer: http://crm.local/datodecontacto/agregar
[Thu Sep 21 11:42:59.363693 2017] [cgi:error] [pid 3019] [client 127.0.0.1:38134] AH01215:     denominacion = form['denominacion'].value, referer: http://crm.local/datodecontacto/agregar
[Thu Sep 21 11:42:59.363728 2017] [cgi:error] [pid 3019] [client 127.0.0.1:38134] AH01215:   File "/usr/lib/python2.7/cgi.py", line 540, in __getitem__, referer: http://crm.local/datodecontacto/agregar
[Thu Sep 21 11:42:59.389008 2017] [cgi:error] [pid 3019] [client 127.0.0.1:38134] AH01215:     raise KeyError, key, referer: http://crm.local/datodecontacto/agregar
[Thu Sep 21 11:42:59.389044 2017] [cgi:error] [pid 3019] [client 127.0.0.1:38134] AH01215: KeyError: , referer: http://crm.local/datodecontacto/agregar
[Thu Sep 21 11:42:59.389057 2017] [cgi:error] [pid 3019] [client 127.0.0.1:38134] AH01215: 'denominacion', referer: http://crm.local/datodecontacto/agregar
[Thu Sep 21 11:42:59.416576 2017] [cgi:error] [pid 3019] [client 127.0.0.1:38134] End of script output before headers: xfc.py, referer: http://crm.local/datodecontacto/agregar
[Thu Sep 21 11:44:13.501252 2017] [cgi:error] [pid 3020] [client 127.0.0.1:38136] AH01215: Traceback (most recent call last):, referer: http://crm.local/datodecontacto/agregar
[Thu Sep 21 11:44:13.501344 2017] [cgi:error] [pid 3020] [client 127.0.0.1:38136] AH01215:   File "/home/debian/server/crm/rootsystem/application/xfc.py", line 17, in <module>, referer: http://crm.local/datodecontacto/agregar
[Thu Sep 21 11:44:13.501364 2017] [cgi:error] [pid 3020] [client 127.0.0.1:38136] AH01215:     getattr(c, recurso)(), referer: http://crm.local/datodecontacto/agregar
[Thu Sep 21 11:44:13.501400 2017] [cgi:error] [pid 3020] [client 127.0.0.1:38136] AH01215:   File "/home/debian/server/crm/rootsystem/application/modules/producto.py", line 102, in guardar, referer: http://crm.local/datodecontacto/agregar
[Thu Sep 21 11:44:13.501422 2017] [cgi:error] [pid 3020] [client 127.0.0.1:38136] AH01215:     denominacion = form['denominacion'].value, referer: http://crm.local/datodecontacto/agregar
[Thu Sep 21 11:44:13.501448 2017] [cgi:error] [pid 3020] [client 127.0.0.1:38136] AH01215:   File "/usr/lib/python2.7/cgi.py", line 540, in __getitem__, referer: http://crm.local/datodecontacto/agregar
[Thu Sep 21 11:44:13.501464 2017] [cgi:error] [pid 3020] [client 127.0.0.1:38136] AH01215:     raise KeyError, key, referer: http://crm.local/datodecontacto/agregar
[Thu Sep 21 11:44:13.501479 2017] [cgi:error] [pid 3020] [client 127.0.0.1:38136] AH01215: KeyError: 'denominacion', referer: http://crm.local/datodecontacto/agregar
[Thu Sep 21 11:44:13.504696 2017] [cgi:error] [pid 3020] [client 127.0.0.1:38136] End of script output before headers: xfc.py, referer: http://crm.local/datodecontacto/agregar
[Thu Sep 21 11:45:04.109687 2017] [cgi:error] [pid 3021] [client 127.0.0.1:38138] AH01215: Traceback (most recent call last):, referer: http://crm.local/datodecontacto/agregar
[Thu Sep 21 11:45:04.109769 2017] [cgi:error] [pid 3021] [client 127.0.0.1:38138] AH01215:   File "/home/debian/server/crm/rootsystem/application/xfc.py", line 17, in <module>, referer: http://crm.local/datodecontacto/agregar
[Thu Sep 21 11:45:04.109784 2017] [cgi:error] [pid 3021] [client 127.0.0.1:38138] AH01215:     getattr(c, recurso)(), referer: http://crm.local/datodecontacto/agregar
[Thu Sep 21 11:45:04.109817 2017] [cgi:error] [pid 3021] [client 127.0.0.1:38138] AH01215:   File "/home/debian/server/crm/rootsystem/application/modules/producto.py", line 102, in guardar, referer: http://crm.local/datodecontacto/agregar
[Thu Sep 21 11:45:04.109837 2017] [cgi:error] [pid 3021] [client 127.0.0.1:38138] AH01215:     denominacion = form['denominacion'].value, referer: http://crm.local/datodecontacto/agregar
[Thu Sep 21 11:45:04.109864 2017] [cgi:error] [pid 3021] [client 127.0.0.1:38138] AH01215:   File "/usr/lib/python2.7/cgi.py", line 540, in __getitem__, referer: http://crm.local/datodecontacto/agregar
[Thu Sep 21 11:45:04.109877 2017] [cgi:error] [pid 3021] [client 127.0.0.1:38138] AH01215:     raise KeyError, key, referer: http://crm.local/datodecontacto/agregar
[Thu Sep 21 11:45:04.109890 2017] [cgi:error] [pid 3021] [client 127.0.0.1:38138] AH01215: KeyError: 'denominacion', referer: http://crm.local/datodecontacto/agregar
[Thu Sep 21 11:45:04.112778 2017] [cgi:error] [pid 3021] [client 127.0.0.1:38138] End of script output before headers: xfc.py, referer: http://crm.local/datodecontacto/agregar
[Thu Sep 21 11:46:56.003963 2017] [cgi:error] [pid 5202] [client 127.0.0.1:38142] AH01215: Traceback (most recent call last):, referer: http://crm.local/datodecontacto/agregar
[Thu Sep 21 11:46:56.004072 2017] [cgi:error] [pid 5202] [client 127.0.0.1:38142] AH01215:   File "/home/debian/server/crm/rootsystem/application/xfc.py", line 17, in <module>, referer: http://crm.local/datodecontacto/agregar
[Thu Sep 21 11:46:56.004091 2017] [cgi:error] [pid 5202] [client 127.0.0.1:38142] AH01215:     getattr(c, recurso)(), referer: http://crm.local/datodecontacto/agregar
[Thu Sep 21 11:46:56.004130 2017] [cgi:error] [pid 5202] [client 127.0.0.1:38142] AH01215:   File "/home/debian/server/crm/rootsystem/application/modules/datodecontacto.py", line 67, in guardar, referer: http://crm.local/datodecontacto/agregar
[Thu Sep 21 11:46:56.004146 2017] [cgi:error] [pid 5202] [client 127.0.0.1:38142] AH01215:     mail = form['mail'].value, referer: http://crm.local/datodecontacto/agregar
[Thu Sep 21 11:46:56.004170 2017] [cgi:error] [pid 5202] [client 127.0.0.1:38142] AH01215: AttributeError: 'list' object has no attribute 'value', referer: http://crm.local/datodecontacto/agregar
[Thu Sep 21 11:46:56.007340 2017] [cgi:error] [pid 5202] [client 127.0.0.1:38142] End of script output before headers: xfc.py, referer: http://crm.local/datodecontacto/agregar
[Thu Sep 21 11:49:04.213601 2017] [cgi:error] [pid 3018] [client 127.0.0.1:38144] AH01215: Traceback (most recent call last):, referer: http://crm.local/datodecontacto/agregar
[Thu Sep 21 11:49:04.213695 2017] [cgi:error] [pid 3018] [client 127.0.0.1:38144] AH01215:   File "/home/debian/server/crm/rootsystem/application/xfc.py", line 17, in <module>, referer: http://crm.local/datodecontacto/agregar
[Thu Sep 21 11:49:04.213713 2017] [cgi:error] [pid 3018] [client 127.0.0.1:38144] AH01215:     getattr(c, recurso)(), referer: http://crm.local/datodecontacto/agregar
[Thu Sep 21 11:49:04.213752 2017] [cgi:error] [pid 3018] [client 127.0.0.1:38144] AH01215:   File "/home/debian/server/crm/rootsystem/application/modules/datodecontacto.py", line 67, in guardar, referer: http://crm.local/datodecontacto/agregar
[Thu Sep 21 11:49:04.213769 2017] [cgi:error] [pid 3018] [client 127.0.0.1:38144] AH01215:     mail = form['mail'].value, referer: http://crm.local/datodecontacto/agregar
[Thu Sep 21 11:49:04.213792 2017] [cgi:error] [pid 3018] [client 127.0.0.1:38144] AH01215: AttributeError: 'list' object has no attribute 'value', referer: http://crm.local/datodecontacto/agregar
[Thu Sep 21 11:49:04.216508 2017] [cgi:error] [pid 3018] [client 127.0.0.1:38144] End of script output before headers: xfc.py, referer: http://crm.local/datodecontacto/agregar
[Thu Sep 21 11:51:16.700628 2017] [cgi:error] [pid 3019] [client 127.0.0.1:38146] AH01215: Traceback (most recent call last):, referer: http://crm.local/datodecontacto/agregar
[Thu Sep 21 11:51:16.700712 2017] [cgi:error] [pid 3019] [client 127.0.0.1:38146] AH01215:   File "/home/debian/server/crm/rootsystem/application/xfc.py", line 17, in <module>, referer: http://crm.local/datodecontacto/agregar
[Thu Sep 21 11:51:16.700729 2017] [cgi:error] [pid 3019] [client 127.0.0.1:38146] AH01215:     getattr(c, recurso)(), referer: http://crm.local/datodecontacto/agregar
[Thu Sep 21 11:51:16.700765 2017] [cgi:error] [pid 3019] [client 127.0.0.1:38146] AH01215:   File "/home/debian/server/crm/rootsystem/application/modules/datodecontacto.py", line 67, in guardar, referer: http://crm.local/datodecontacto/agregar
[Thu Sep 21 11:51:16.700780 2017] [cgi:error] [pid 3019] [client 127.0.0.1:38146] AH01215:     mail = form['mail'].value, referer: http://crm.local/datodecontacto/agregar
[Thu Sep 21 11:51:16.700804 2017] [cgi:error] [pid 3019] [client 127.0.0.1:38146] AH01215: AttributeError: 'list' object has no attribute 'value', referer: http://crm.local/datodecontacto/agregar
[Thu Sep 21 11:51:16.703734 2017] [cgi:error] [pid 3019] [client 127.0.0.1:38146] End of script output before headers: xfc.py, referer: http://crm.local/datodecontacto/agregar
[Thu Sep 21 11:55:03.222822 2017] [cgi:error] [pid 3020] [client 127.0.0.1:38148] AH01215: Traceback (most recent call last):, referer: http://crm.local/datodecontacto/agregar
[Thu Sep 21 11:55:03.222904 2017] [cgi:error] [pid 3020] [client 127.0.0.1:38148] AH01215:   File "/home/debian/server/crm/rootsystem/application/xfc.py", line 17, in <module>, referer: http://crm.local/datodecontacto/agregar
[Thu Sep 21 11:55:03.222922 2017] [cgi:error] [pid 3020] [client 127.0.0.1:38148] AH01215:     getattr(c, recurso)(), referer: http://crm.local/datodecontacto/agregar
[Thu Sep 21 11:55:03.222958 2017] [cgi:error] [pid 3020] [client 127.0.0.1:38148] AH01215:   File "/home/debian/server/crm/rootsystem/application/modules/datodecontacto.py", line 67, in guardar, referer: http://crm.local/datodecontacto/agregar
[Thu Sep 21 11:55:03.222974 2017] [cgi:error] [pid 3020] [client 127.0.0.1:38148] AH01215:     mail = form['mail'].value, referer: http://crm.local/datodecontacto/agregar
[Thu Sep 21 11:55:03.222995 2017] [cgi:error] [pid 3020] [client 127.0.0.1:38148] AH01215: AttributeError: 'list' object has no attribute 'value', referer: http://crm.local/datodecontacto/agregar
[Thu Sep 21 11:55:03.226003 2017] [cgi:error] [pid 3020] [client 127.0.0.1:38148] End of script output before headers: xfc.py, referer: http://crm.local/datodecontacto/agregar
[Thu Sep 21 12:02:44.335881 2017] [cgi:error] [pid 3021] [client 127.0.0.1:38150] AH01215: Traceback (most recent call last):, referer: http://crm.local/datodecontacto/agregar
[Thu Sep 21 12:02:44.335971 2017] [cgi:error] [pid 3021] [client 127.0.0.1:38150] AH01215:   File "/home/debian/server/crm/rootsystem/application/xfc.py", line 17, in <module>, referer: http://crm.local/datodecontacto/agregar
[Thu Sep 21 12:02:44.335990 2017] [cgi:error] [pid 3021] [client 127.0.0.1:38150] AH01215:     getattr(c, recurso)(), referer: http://crm.local/datodecontacto/agregar
[Thu Sep 21 12:02:44.336029 2017] [cgi:error] [pid 3021] [client 127.0.0.1:38150] AH01215:   File "/home/debian/server/crm/rootsystem/application/modules/datodecontacto.py", line 68, in guardar, referer: http://crm.local/datodecontacto/agregar
[Thu Sep 21 12:02:44.336046 2017] [cgi:error] [pid 3021] [client 127.0.0.1:38150] AH01215:     mail = form['mail'].value, referer: http://crm.local/datodecontacto/agregar
[Thu Sep 21 12:02:44.336073 2017] [cgi:error] [pid 3021] [client 127.0.0.1:38150] AH01215: AttributeError: 'list' object has no attribute 'value', referer: http://crm.local/datodecontacto/agregar
[Thu Sep 21 12:02:44.338997 2017] [cgi:error] [pid 3021] [client 127.0.0.1:38150] End of script output before headers: xfc.py, referer: http://crm.local/datodecontacto/agregar
[Thu Sep 21 12:02:59.492261 2017] [cgi:error] [pid 3017] [client 127.0.0.1:38152] AH01215: Traceback (most recent call last):, referer: http://crm.local/datodecontacto/agregar
[Thu Sep 21 12:02:59.492368 2017] [cgi:error] [pid 3017] [client 127.0.0.1:38152] AH01215:   File "/home/debian/server/crm/rootsystem/application/xfc.py", line 17, in <module>, referer: http://crm.local/datodecontacto/agregar
[Thu Sep 21 12:02:59.492388 2017] [cgi:error] [pid 3017] [client 127.0.0.1:38152] AH01215:     getattr(c, recurso)(), referer: http://crm.local/datodecontacto/agregar
[Thu Sep 21 12:02:59.492427 2017] [cgi:error] [pid 3017] [client 127.0.0.1:38152] AH01215:   File "/home/debian/server/crm/rootsystem/application/modules/datodecontacto.py", line 68, in guardar, referer: http://crm.local/datodecontacto/agregar
[Thu Sep 21 12:02:59.492445 2017] [cgi:error] [pid 3017] [client 127.0.0.1:38152] AH01215:     mail = form['mail'].value, referer: http://crm.local/datodecontacto/agregar
[Thu Sep 21 12:02:59.492473 2017] [cgi:error] [pid 3017] [client 127.0.0.1:38152] AH01215: AttributeError: 'list' object has no attribute 'value', referer: http://crm.local/datodecontacto/agregar
[Thu Sep 21 12:02:59.495894 2017] [cgi:error] [pid 3017] [client 127.0.0.1:38152] End of script output before headers: xfc.py, referer: http://crm.local/datodecontacto/agregar
[Thu Sep 21 12:09:14.817413 2017] [cgi:error] [pid 5202] [client 127.0.0.1:38254] AH01215: Traceback (most recent call last):, referer: http://crm.local/datodecontacto/agregar
[Thu Sep 21 12:09:14.817500 2017] [cgi:error] [pid 5202] [client 127.0.0.1:38254] AH01215:   File "/home/debian/server/crm/rootsystem/application/xfc.py", line 17, in <module>, referer: http://crm.local/datodecontacto/agregar
[Thu Sep 21 12:09:14.817520 2017] [cgi:error] [pid 5202] [client 127.0.0.1:38254] AH01215:     getattr(c, recurso)(), referer: http://crm.local/datodecontacto/agregar
[Thu Sep 21 12:09:14.817561 2017] [cgi:error] [pid 5202] [client 127.0.0.1:38254] AH01215:   File "/home/debian/server/crm/rootsystem/application/modules/datodecontacto.py", line 68, in guardar, referer: http://crm.local/datodecontacto/agregar
[Thu Sep 21 12:09:14.817580 2017] [cgi:error] [pid 5202] [client 127.0.0.1:38254] AH01215:     mail = form['mail'].value, referer: http://crm.local/datodecontacto/agregar
[Thu Sep 21 12:09:14.817604 2017] [cgi:error] [pid 5202] [client 127.0.0.1:38254] AH01215: AttributeError: 'list' object has no attribute 'value', referer: http://crm.local/datodecontacto/agregar
[Thu Sep 21 12:09:14.821711 2017] [cgi:error] [pid 5202] [client 127.0.0.1:38254] End of script output before headers: xfc.py, referer: http://crm.local/datodecontacto/agregar
[Thu Sep 21 12:09:47.556175 2017] [cgi:error] [pid 3018] [client 127.0.0.1:38256] AH01215: Traceback (most recent call last):, referer: http://crm.local/datodecontacto/agregar
[Thu Sep 21 12:09:47.556258 2017] [cgi:error] [pid 3018] [client 127.0.0.1:38256] AH01215:   File "/home/debian/server/crm/rootsystem/application/xfc.py", line 17, in <module>, referer: http://crm.local/datodecontacto/agregar
[Thu Sep 21 12:09:47.556275 2017] [cgi:error] [pid 3018] [client 127.0.0.1:38256] AH01215:     getattr(c, recurso)(), referer: http://crm.local/datodecontacto/agregar
[Thu Sep 21 12:09:47.556312 2017] [cgi:error] [pid 3018] [client 127.0.0.1:38256] AH01215:   File "/home/debian/server/crm/rootsystem/application/modules/datodecontacto.py", line 68, in guardar, referer: http://crm.local/datodecontacto/agregar
[Thu Sep 21 12:09:47.556328 2017] [cgi:error] [pid 3018] [client 127.0.0.1:38256] AH01215:     mail = form['mail'].value, referer: http://crm.local/datodecontacto/agregar
[Thu Sep 21 12:09:47.556350 2017] [cgi:error] [pid 3018] [client 127.0.0.1:38256] AH01215: AttributeError: 'list' object has no attribute 'value', referer: http://crm.local/datodecontacto/agregar
[Thu Sep 21 12:09:47.559203 2017] [cgi:error] [pid 3018] [client 127.0.0.1:38256] End of script output before headers: xfc.py, referer: http://crm.local/datodecontacto/agregar
[Thu Sep 21 12:11:59.531590 2017] [cgi:error] [pid 3019] [client 127.0.0.1:38258] AH01215: Traceback (most recent call last):, referer: http://crm.local/datodecontacto/agregar
[Thu Sep 21 12:11:59.531681 2017] [cgi:error] [pid 3019] [client 127.0.0.1:38258] AH01215:   File "/home/debian/server/crm/rootsystem/application/xfc.py", line 17, in <module>, referer: http://crm.local/datodecontacto/agregar
[Thu Sep 21 12:11:59.531701 2017] [cgi:error] [pid 3019] [client 127.0.0.1:38258] AH01215:     getattr(c, recurso)(), referer: http://crm.local/datodecontacto/agregar
[Thu Sep 21 12:11:59.531741 2017] [cgi:error] [pid 3019] [client 127.0.0.1:38258] AH01215:   File "/home/debian/server/crm/rootsystem/application/modules/datodecontacto.py", line 68, in guardar, referer: http://crm.local/datodecontacto/agregar
[Thu Sep 21 12:11:59.531758 2017] [cgi:error] [pid 3019] [client 127.0.0.1:38258] AH01215:     mail = form['mail'].value, referer: http://crm.local/datodecontacto/agregar
[Thu Sep 21 12:11:59.531783 2017] [cgi:error] [pid 3019] [client 127.0.0.1:38258] AH01215: AttributeError: 'list' object has no attribute 'value', referer: http://crm.local/datodecontacto/agregar
[Thu Sep 21 12:11:59.536337 2017] [cgi:error] [pid 3019] [client 127.0.0.1:38258] End of script output before headers: xfc.py, referer: http://crm.local/datodecontacto/agregar
[Thu Sep 21 14:55:43.781045 2017] [cgi:error] [pid 1143] [client 127.0.0.1:36752] AH01215: Traceback (most recent call last):
[Thu Sep 21 14:55:43.866744 2017] [cgi:error] [pid 1143] [client 127.0.0.1:36752] AH01215:   File "/home/debian/server/crm/rootsystem/application/xfc.py", line 12, in <module>
[Thu Sep 21 14:55:43.866784 2017] [cgi:error] [pid 1143] [client 127.0.0.1:36752] AH01215:     recurso = uri[2]
[Thu Sep 21 14:55:43.866798 2017] [cgi:error] [pid 1143] [client 127.0.0.1:36752] AH01215: IndexError: list index out of range
[Thu Sep 21 14:55:43.866829 2017] [cgi:error] [pid 1143] [client 127.0.0.1:36752] End of script output before headers: xfc.py
[Thu Sep 21 15:27:29.368689 2017] [cgi:error] [pid 1145] [client 127.0.0.1:36796] AH01215: Traceback (most recent call last):
[Thu Sep 21 15:27:29.368814 2017] [cgi:error] [pid 1145] [client 127.0.0.1:36796] AH01215:   File "/home/debian/server/crm/rootsystem/application/xfc.py", line 17, in <module>
[Thu Sep 21 15:27:29.368830 2017] [cgi:error] [pid 1145] [client 127.0.0.1:36796] AH01215:     getattr(c, recurso)()
[Thu Sep 21 15:27:29.368853 2017] [cgi:error] [pid 1145] [client 127.0.0.1:36796] AH01215: TypeError: editar() takes exactly 2 arguments (1 given)
[Thu Sep 21 15:27:29.371545 2017] [cgi:error] [pid 1145] [client 127.0.0.1:36796] End of script output before headers: xfc.py
[Thu Sep 21 15:29:48.364015 2017] [cgi:error] [pid 1147] [client 127.0.0.1:36802] AH01215: Traceback (most recent call last):, referer: http://crm.local/datodecontacto/editar/1
[Thu Sep 21 15:29:48.364155 2017] [cgi:error] [pid 1147] [client 127.0.0.1:36802] AH01215:   File "/home/debian/server/crm/rootsystem/application/xfc.py", line 17, in <module>, referer: http://crm.local/datodecontacto/editar/1
[Thu Sep 21 15:29:48.364173 2017] [cgi:error] [pid 1147] [client 127.0.0.1:36802] AH01215:     getattr(c, recurso)(), referer: http://crm.local/datodecontacto/editar/1
[Thu Sep 21 15:29:48.364205 2017] [cgi:error] [pid 1147] [client 127.0.0.1:36802] AH01215: AttributeError: 'DatodecontactoController' object has no attribute 'actualizar', referer: http://crm.local/datodecontacto/editar/1
[Thu Sep 21 15:29:48.367459 2017] [cgi:error] [pid 1147] [client 127.0.0.1:36802] End of script output before headers: xfc.py, referer: http://crm.local/datodecontacto/editar/1
[Tue Sep 26 14:00:17.799889 2017] [cgi:error] [pid 1253] [client 127.0.0.1:48910] AH01215: Traceback (most recent call last):
[Tue Sep 26 14:00:17.848554 2017] [cgi:error] [pid 1253] [client 127.0.0.1:48910] AH01215:   File "/home/debian/server/crm/rootsystem/application/xfc.py", line 12, in <module>
[Tue Sep 26 14:00:17.848576 2017] [cgi:error] [pid 1253] [client 127.0.0.1:48910] AH01215:     recurso = uri[2]
[Tue Sep 26 14:00:17.848588 2017] [cgi:error] [pid 1253] [client 127.0.0.1:48910] AH01215: IndexError: list index out of range
[Tue Sep 26 14:00:17.848609 2017] [cgi:error] [pid 1253] [client 127.0.0.1:48910] End of script output before headers: xfc.py
